Workbook

Sheet Gateways_DynamoDB
A1: operator_name | B1: operator_id | C1: id | D1: sn | E1: case_nr | F1: settings | G1: wagon_nr | H1: imei | I1: board_model | J1: battery_mah | K1: installation_date | L1: placement | M1: installed_by | N1: note | O1: setting_string
B2: =IFERROR(INDEX(Companies!$A$3:$A$101,MATCH(A2,Companies!$B$3:$B$101,0)),"") | C2: e00fce68d5f6b9fb3caee958 | E2: GW2203-006 | F2: Shipping | I2: T523M | J2: 19800 | O2: =IFERROR(INDEX(Settings!$AC$3:$AC$95,MATCH(Gateways_DynamoDB!$F2,Settings!$B$3:$B$95,0)),"")
B3: =IFERROR(INDEX(Companies!$A$3:$A$101,MATCH(A3,Companies!$B$3:$B$101,0)),"") | C3: e00fce68fe4dbdb9fab37607 | E3: GW2203-017 | F3: Shipping | I3: T523M | J3: 19800 | N3: REFURBISHED | O3: =IFERROR(INDEX(Settings!$AC$3:$AC$95,MATCH(Gateways_DynamoDB!$F3,Settings!$B$3:$B$95,0)),"")
A4: TANKWAGON | B4: =IFERROR(INDEX(Companies!$A$3:$A$101,MATCH(A4,Companies!$B$3:$B$101,0)),"") | C4: e00fce6887c2f1e171208217 | E4: GW2203-019 | F4: Slow-5-12h | G4: 33877916669-7 | I4: T523M | J4: 19800 | O4: =IFERROR(INDEX(Settings!$AC$3:$AC$95,MATCH(Gateways_DynamoDB!$F4,Settings!$B$3:$B$95,0)),"")
A5: =IFERROR(INDEX(Gateways_MANU!$A$2:$A$4949,MATCH($E5,Gateways_MANU!$B$2:$B$4949,0)),"") | B5: =IFERROR(INDEX(Companies!$A$3:$A$101,MATCH(A5,Companies!$B$3:$B$101,0)),"") | C5: e00fce688ca17b3f3592c148 | E5: GW2203-024 | F5: Shipping | G5: 33854956687-9 | I5: T523M | J5: 19800 | K5: 44832 | L5: L | M5: Hupac | N5: REFURBISHED | O5: =IFERROR(INDEX(Settings!$AC$3:$AC$95,MATCH(Gateways_DynamoDB!$F5,Settings!$B$3:$B$95,0)),"")
B6: =IFERROR(INDEX(Companies!$A$3:$A$101,MATCH(A6,Companies!$B$3:$B$101,0)),"") | C6: e00fce68c836b123fe66b5cc | E6: GW2203-031 | F6: Shipping | I6: T523M | J6: 19800 | N6: REFURBISHED | O6: =IFERROR(INDEX(Settings!$AC$3:$AC$95,MATCH(Gateways_DynamoDB!$F6,Settings!$B$3:$B$95,0)),"")
B7: =IFERROR(INDEX(Companies!$A$3:$A$101,MATCH(A7,Companies!$B$3:$B$101,0)),"") | C7: e00fce68937b6b32fe0ec8c3 | E7: GW2203-035 | F7: Shipping | I7: T523M | J7: 19800 | N7: REFURBISHED | O7: =IFERROR(INDEX(Settings!$AC$3:$AC$95,MATCH(Gateways_DynamoDB!$F7,Settings!$B$3:$B$95,0)),"")
A8: =IFERROR(INDEX(Gateways_MANU!$A$2:$A$4949,MATCH($E8,Gateways_MANU!$B$2:$B$4949,0)),"") | B8: =IFERROR(INDEX(Companies!$A$3:$A$101,MATCH(A8,Companies!$B$3:$B$101,0)),"") | C8: e00fce68f75fe3eac5ee7b0a | E8: GW2203-037 | F8: Shipping | G8: 33854506155-2 | I8: T523M | J8: 19800 | K8: 44832 | L8: L | M8: Hupac | N8: REFURBISHED | O8: =IFERROR(INDEX(Settings!$AC$3:$AC$95,MATCH(Gateways_DynamoDB!$F8,Settings!$B$3:$B$95,0)),"")
C9: e00fce6843cf275e71c9114a | E9: GW2203-043 | F9: Shipping | I9: T523M | J9: 19800 | N9: REFURBISHED | O9: =IFERROR(INDEX(Settings!$AC$3:$AC$95,MATCH(Gateways_DynamoDB!$F9,Settings!$B$3:$B$95,0)),"")
B10: =IFERROR(INDEX(Companies!$A$3:$A$101,MATCH(A10,Companies!$B$3:$B$101,0)),"") | C10: e00fce6896f7577f9882a05e | D10: P025AB035NST2GY | E10: GW2206-011 | F10: Shipping | I10: T523M | J10: =6600*3 | O10: =IFERROR(INDEX(Settings!$AC$3:$AC$95,MATCH(Gateways_DynamoDB!$F10,Settings!$B$3:$B$95,0)),"")
A11: TANKWAGON | B11: =IFERROR(INDEX(Companies!$A$3:$A$101,MATCH(A11,Companies!$B$3:$B$101,0)),"") | C11: e00fce68ad614837daa82ef5 | D11: P025AB110CYFGSN | E11: GW2206-060 | F11: Slow-5-12h | G11: 33747913061-5 | I11: T523M | J11: =6600*3 | O11: =IFERROR(INDEX(Settings!$AC$3:$AC$95,MATCH(Gateways_DynamoDB!$F11,Settings!$B$3:$B$95,0)),"")
A12: HUPAC | B12: =IFERROR(INDEX(Companies!$A$3:$A$101,MATCH(A12,Companies!$B$3:$B$101,0)),"") | C12: e00fce68fabaf7b85132d014 | D12: P025AB106R9KDYH | E12: GW2206-089 | F12: Shipping | G12: 33854956687-9 | I12: T523M | J12: =6600*3 | K12: 44832 | L12: R | M12: Hupac | N12: REFURBISHED | O12: =IFERROR(INDEX(Settings!$AC$3:$AC$95,MATCH(Gateways_DynamoDB!$F12,Settings!$B$3:$B$95,0)),"")
A13: VTG | B13: =IFERROR(INDEX(Companies!$A$3:$A$101,MATCH(A13,Companies!$B$3:$B$101,0)),"") | C13: e00fce68460536b41089cff8 | D13: P025AB029SKJB5U | E13: GW2203-041 | F13: Shipping | H13: 867648041711084 | I13: T523M | J13: 19800 | N13: The device is with VTG, would like to get it back. Not monitored on Ubidots anymore. | O13: =IFERROR(INDEX(Settings!$AC$3:$AC$95,MATCH(Gateways_DynamoDB!$F13,Settings!$B$3:$B$95,0)),"")
A14: VTG | B14: =IFERROR(INDEX(Companies!$A$3:$A$101,MATCH(A14,Companies!$B$3:$B$101,0)),"") | C14: e00fce6851355da59013f2c4 | E14: GW2206-086 | F14: Shipping | N14: The device is with VTG, would like to get it back. Not monitored on Ubidots anymore. | O14: =IFERROR(INDEX(Settings!$AC$3:$AC$95,MATCH(Gateways_DynamoDB!$F14,Settings!$B$3:$B$95,0)),"")
A15: TANKWAGON | B15: =IFERROR(INDEX(Companies!$A$3:$A$101,MATCH(A15,Companies!$B$3:$B$101,0)),"") | C15: e00fce68dcd8c78ed63ea671 | E15: GW2203-022 | F15: Shipping | G15: 33857929905-2 | I15: T523M | J15: =3*6600 | K15: 45210 | L15: L | M15: TANKWAGON | N15: REFURBISHED | O15: =IFERROR(INDEX(Settings!$AC$3:$AC$95,MATCH(Gateways_DynamoDB!$F15,Settings!$B$3:$B$95,0)),"")
A16: AMBROGIO | B16: =IFERROR(INDEX(Companies!$A$3:$A$101,MATCH(A16,Companies!$B$3:$B$101,0)),"") | C16: e00fce68afcedd2b5f45923c | D16: P025AB029VMW27B | E16: GW2206-039 | F16: Shipping | G16: 33-83-495-4-940-6 | I16: T523M | J16: =6600*3 | K16: 44832 | L16: L | M16: Viezo | O16: =IFERROR(INDEX(Settings!$AC$3:$AC$95,MATCH(Gateways_DynamoDB!$F16,Settings!$B$3:$B$95,0)),"")
A17: TRANSFESA | B17: =IFERROR(INDEX(Companies!$A$3:$A$101,MATCH(A17,Companies!$B$3:$B$101,0)),"") | C17: e00fce6819fe1dab0cbaa87e | D17: P025AB028DKE4WY | E17: GW2206-077 | F17: Shipping | G17: 24714450036-7 | H17: 867648041714096 | I17: T523M | J17: 19800 | K17: 44893 | O17: =IFERROR(INDEX(Settings!$AC$3:$AC$95,MATCH(Gateways_DynamoDB!$F17,Settings!$B$3:$B$95,0)),"")
A18: TANKWAGON | B18: =IFERROR(INDEX(Companies!$A$3:$A$101,MATCH(A18,Companies!$B$3:$B$101,0)),"") | C18: e00fce68c2592b9188efd2c9 | D18: P025AB028C6AVWK | E18: GW2203-021 | F18: Slow-5-12h | G18: 33877916663-0 | H18: 867648041704329 | I18: T523M | J18: 19800 | N18: was_GW2206-080 | O18: =IFERROR(INDEX(Settings!$AC$3:$AC$95,MATCH(Gateways_DynamoDB!$F18,Settings!$B$3:$B$95,0)),"")
A19: TANKWAGON | B19: =IFERROR(INDEX(Companies!$A$3:$A$101,MATCH(A19,Companies!$B$3:$B$101,0)),"") | C19: e00fce68122c671cbe1f1ff1 | E19: GW2203-003 | F19: Slow-5-12h | G19: 33877916666-3 | O19: =IFERROR(INDEX(Settings!$AC$3:$AC$95,MATCH(Gateways_DynamoDB!$F19,Settings!$B$3:$B$95,0)),"")
B20: =IFERROR(INDEX(Companies!$A$3:$A$101,MATCH(A20,Companies!$B$3:$B$101,0)),"") | C20: e00fce683054951baa398b52 | E20: GW2203-015 | F20: Shipping | O20: =IFERROR(INDEX(Settings!$AC$3:$AC$95,MATCH(Gateways_DynamoDB!$F20,Settings!$B$3:$B$95,0)),"")
A21: RAILIZE | B21: =IFERROR(INDEX(Companies!$A$3:$A$101,MATCH(A21,Companies!$B$3:$B$101,0)),"") | C21: e00fce68fee664d352aabbb4 | D21: P025AB028UWJH3K | E21: GW2206-061 | F21: Shipping | H21: 867648041664994 | I21: T523M | J21: 19800 | O21: =IFERROR(INDEX(Settings!$AC$3:$AC$95,MATCH(Gateways_DynamoDB!$F21,Settings!$B$3:$B$95,0)),"")
A22: =IFERROR(INDEX(Gateways_MANU!$A$2:$A$4949,MATCH($E22,Gateways_MANU!$B$2:$B$4949,0)),"") | B22: =IFERROR(INDEX(Companies!$A$3:$A$101,MATCH(A22,Companies!$B$3:$B$101,0)),"") | C22: e00fce68f7915cebf1562e87 | E22: GW2203-007 | F22: Shipping | G22: 3354-3937-523-9 | J22: 19800 | K22: 44888 | M22: SGL | N22: The operator has the device or its lost (they paid for it), but we dont monitor it on Ubidots anymore. | O22: =IFERROR(INDEX(Settings!$AC$3:$AC$95,MATCH(Gateways_DynamoDB!$F22,Settings!$B$3:$B$95,0)),"")
A23: =IFERROR(INDEX(Gateways_MANU!$A$2:$A$4949,MATCH($E23,Gateways_MANU!$B$2:$B$4949,0)),"") | B23: =IFERROR(INDEX(Companies!$A$3:$A$101,MATCH(A23,Companies!$B$3:$B$101,0)),"") | C23: e00fce6831de67dd448473e9 | D23: P025AB0296GK27H | E23: GW2206-094 | F23: Shipping | G23: 83546985088-6 | H23: 867648041698265 | J23: =3*6600 | K23: 44909 | L23: R | M23: HVLE | N23: 44876 | O23: =IFERROR(INDEX(Settings!$AC$3:$AC$95,MATCH(Gateways_DynamoDB!$F23,Settings!$B$3:$B$95,0)),"")
A24: CFLCARGO | B24: =IFERROR(INDEX(Companies!$A$3:$A$101,MATCH(A24,Companies!$B$3:$B$101,0)),"") | C24: e00fce6884e6fce92e4a8614 | D24: P025AB110468W3Y | E24: GW2206-093 | F24: Normal-2-6h | G24: MAK314 | I24: T523M | J24: =6600*3 | O24: =IFERROR(INDEX(Settings!$AC$3:$AC$95,MATCH(Gateways_DynamoDB!$F24,Settings!$B$3:$B$95,0)),"")
A25: =IFERROR(T(INDEX(Gateways_MANU!$A$2:$A$4949,MATCH($E25,Gateways_MANU!$B$2:$B$4949,0))),"") | B25: =IFERROR(INDEX(Companies!$A$3:$A$101,MATCH(A25,Companies!$B$3:$B$101,0)),"") | C25: e00fce68e97726618903cccc | D25: P025AB029EJ2594 | E25: GW2206-084 | F25: Shipping | G25: 33854668206-7 | I25: T523M | J25: =6600*3 | K25: 44918 | L25: L | M25: Viezo | O25: =IFERROR(INDEX(Settings!$AC$3:$AC$95,MATCH(Gateways_DynamoDB!$F25,Settings!$B$3:$B$95,0)),"")
A26: RENFE | B26: =IFERROR(INDEX(Companies!$A$3:$A$101,MATCH(A26,Companies!$B$3:$B$101,0)),"") | C26: e00fce6806eb219a43754b61 | D26: P025AB1109GN7DK | E26: GW2203-027 | F26: Shipping | G26: 527017 | I26: T523M | J26: =6600*3 | O26: =IFERROR(INDEX(Settings!$AC$3:$AC$95,MATCH(Gateways_DynamoDB!$F26,Settings!$B$3:$B$95,0)),"")
A27: TANKWAGON | B27: =IFERROR(INDEX(Companies!$A$3:$A$101,MATCH(A27,Companies!$B$3:$B$101,0)),"") | C27: e00fce68193d8bb1b06adc22 | D27: P025AB110H6FVU3 | E27: GW2206-019 | F27: Slow-5-12h | G27: 33877916681-2 | I27: T523M | J27: =6600*3 | O27: =IFERROR(INDEX(Settings!$AC$3:$AC$95,MATCH(Gateways_DynamoDB!$F27,Settings!$B$3:$B$95,0)),"")
A28: =IFERROR(INDEX(Gateways_MANU!$A$2:$A$4949,MATCH($E28,Gateways_MANU!$B$2:$B$4949,0)),"") | B28: =IFERROR(INDEX(Companies!$A$3:$A$101,MATCH(A28,Companies!$B$3:$B$101,0)),"") | C28: e00fce68fddc3f4dcf9a3b74 | E28: GW2203-034 | F28: Shipping | N28: The operator has the device or its lost (they paid for it), but we dont monitor it on Ubidots anymore. | O28: =IFERROR(INDEX(Settings!$AC$3:$AC$95,MATCH(Gateways_DynamoDB!$F28,Settings!$B$3:$B$95,0)),"")
A29: =IFERROR(INDEX(Gateways_MANU!$A$2:$A$4949,MATCH($E29,Gateways_MANU!$B$2:$B$4949,0)),"") | B29: =IFERROR(INDEX(Companies!$A$3:$A$101,MATCH(A29,Companies!$B$3:$B$101,0)),"") | C29: e00fce6853420f8642781437 | E29: GW2203-049 | F29: Shipping | N29: The operator has the device or its lost (they paid for it), but we dont monitor it on Ubidots anymore. | O29: =IFERROR(INDEX(Settings!$AC$3:$AC$95,MATCH(Gateways_DynamoDB!$F29,Settings!$B$3:$B$95,0)),"")
A30: =IFERROR(INDEX(Gateways_MANU!$A$2:$A$4949,MATCH($E30,Gateways_MANU!$B$2:$B$4949,0)),"") | B30: =IFERROR(INDEX(Companies!$A$3:$A$101,MATCH(A30,Companies!$B$3:$B$101,0)),"") | C30: e00fce68d32ab7e19cf847bf | F30: Shipping | G30: 84515332773-7 | K30: 44873 | L30: R | M30: Viezo | O30: =IFERROR(INDEX(Settings!$AC$3:$AC$95,MATCH(Gateways_DynamoDB!$F30,Settings!$B$3:$B$95,0)),"")
A31: CFLCARGO | B31: =IFERROR(INDEX(Companies!$A$3:$A$101,MATCH(A31,Companies!$B$3:$B$101,0)),"") | C31: e00fce686488370d15054e7b | D31: P025AB029H378CD | E31: GW2206-056 | F31: Normal-2-6h | G31: MAK309 | N31: was GW2203-012 | O31: =IFERROR(INDEX(Settings!$AC$3:$AC$95,MATCH(Gateways_DynamoDB!$F31,Settings!$B$3:$B$95,0)),"")
A32: =IFERROR(INDEX(Gateways_MANU!$A$2:$A$4949,MATCH($E32,Gateways_MANU!$B$2:$B$4949,0)),"") | B32: =IFERROR(INDEX(Companies!$A$3:$A$101,MATCH(A32,Companies!$B$3:$B$101,0)),"") | C32: e00fce6813144c5e8a15791e | E32: GW2203-023 | F32: Shipping | G32: R3555 | K32: 44862 | M32: Fertagus | O32: =IFERROR(INDEX(Settings!$AC$3:$AC$95,MATCH(Gateways_DynamoDB!$F32,Settings!$B$3:$B$95,0)),"")
A33: FERTAGUS | B33: =IFERROR(INDEX(Companies!$A$3:$A$101,MATCH(A33,Companies!$B$3:$B$101,0)),"") | C33: e00fce68962f04b2507c174f | D33: P025AB0293NU7YX | E33: GW2203-020 | F33: Shipping | G33: M3555 | K33: 44862 | M33: Fertagus | O33: =IFERROR(INDEX(Settings!$AC$3:$AC$95,MATCH(Gateways_DynamoDB!$F33,Settings!$B$3:$B$95,0)),"")
A34: =IFERROR(T(INDEX(Gateways_MANU!$A$2:$A$4949,MATCH($E34,Gateways_MANU!$B$2:$B$4949,0))),"") | B34: =IFERROR(INDEX(Companies!$A$3:$A$101,MATCH(A34,Companies!$B$3:$B$101,0)),"") | C34: e00fce68435a9c417f84ebb9 | D34: P025AB110SCH4BF | E34: was_GW2206-091_ | F34: Shipping | I34: T523M | J34: =6600*3 | O34: =IFERROR(INDEX(Settings!$AC$3:$AC$95,MATCH(Gateways_DynamoDB!$F34,Settings!$B$3:$B$95,0)),"")
A35: =IFERROR(T(INDEX(Gateways_MANU!$A$2:$A$4949,MATCH($E35,Gateways_MANU!$B$2:$B$4949,0))),"") | B35: =IFERROR(INDEX(Companies!$A$3:$A$101,MATCH(A35,Companies!$B$3:$B$101,0)),"") | C35: e00fce682cc4e7703b017399 | D35: P025AB106B7TCKY | E35: GW2206-092 | F35: Shipping | G35: 31834589939-3 | I35: T523M | J35: =6600*3 | M35: Mercitalia | O35: =IFERROR(INDEX(Settings!$AC$3:$AC$95,MATCH(Gateways_DynamoDB!$F35,Settings!$B$3:$B$95,0)),"")
A36: =IFERROR(INDEX(Gateways_MANU!$A$2:$A$4949,MATCH($E36,Gateways_MANU!$B$2:$B$4949,0)),"") | B36: =IFERROR(INDEX(Companies!$A$3:$A$101,MATCH(A36,Companies!$B$3:$B$101,0)),"") | C36: e00fce68109636a0fd8cf124 | E36: GW2206-083 | F36: Shipping | G36: 83546985085-2 | I36: T523M | J36: 19800 | K36: 44880 | L36: L | M36: Viezo | N36: 44876 | O36: =IFERROR(INDEX(Settings!$AC$3:$AC$95,MATCH(Gateways_DynamoDB!$F36,Settings!$B$3:$B$95,0)),"")
A37: =IFERROR(INDEX(Gateways_MANU!$A$2:$A$4949,MATCH($E37,Gateways_MANU!$B$2:$B$4949,0)),"") | B37: =IFERROR(INDEX(Companies!$A$3:$A$101,MATCH(A37,Companies!$B$3:$B$101,0)),"") | C37: e00fce68a175ae2bbe0a0169 | E37: GW2203-026 | F37: Shipping | G37: 31833916501-7 | I37: T523M | J37: 19800 | M37: Mercitalia | O37: =IFERROR(INDEX(Settings!$AC$3:$AC$95,MATCH(Gateways_DynamoDB!$F37,Settings!$B$3:$B$95,0)),"")
A38: TRANSFESA | B38: =IFERROR(INDEX(Companies!$A$3:$A$101,MATCH(A38,Companies!$B$3:$B$101,0)),"") | C38: e00fce68d6e6b7a6e0da65b2 | E38: GW2203-047 | F38: Shipping | G38: 43714378393-8 | I38: T523M | J38: 19800 | K38: 44893 | O38: =IFERROR(INDEX(Settings!$AC$3:$AC$95,MATCH(Gateways_DynamoDB!$F38,Settings!$B$3:$B$95,0)),"")
B39: =IFERROR(INDEX(Companies!$A$3:$A$101,MATCH(A39,Companies!$B$3:$B$101,0)),"") | C39: e00fce6854a172d6ecf1f509 | D39: P025AB0348L7M2T | E39: GW2205-TR01 | F39: Shipping | H39: 867648041668953 | I39: T523M | J39: 19800 | N39: warranty | O39: =IFERROR(INDEX(Settings!$AC$3:$AC$95,MATCH(Gateways_DynamoDB!$F39,Settings!$B$3:$B$95,0)),"")
B40: =IFERROR(INDEX(Companies!$A$3:$A$101,MATCH(A40,Companies!$B$3:$B$101,0)),"") | C40: e00fce689be64a638dd177f1 | D40: P025AB0347GFU25 | E40: GW2205-TR02 | F40: Shipping | I40: T523M | N40: warranty | O40: =IFERROR(INDEX(Settings!$AC$3:$AC$95,MATCH(Gateways_DynamoDB!$F40,Settings!$B$3:$B$95,0)),"")
...

Sheet Sensors_DynamoDB
A1: operator_name | B1: operator_id | C1: wagon_type | D1: mac_addr | E1: mac_addr_full | F1: installation_date | G1: installed_by | H1: sn | I1: harvester_id | J1: case_nr | K1: wagon_nr | L1: placement | M1: axle_nr | N1: note | O1: fw_version | P1: pcb_sn
A2: =IFERROR(_xlfn.IFNA(INDEX(Sensors_MANU!$E$2:$E$4692,MATCH($D2,Sensors_MANU!$B$2:$B$4692,0)),INDEX(Sensors_MANU!$E$2:$E$4692,MATCH($P2,Sensors_MANU!$A$2:$A$4692,0))),"") | B2: =IFERROR(INDEX(Companies!$A$3:$A$101,MATCH(A2,Companies!$B$3:$B$101,0)),"") | C2: Cargo | D2: EC5EDE1E5DAC | E2: =LEFT(D2,2)&":"&MID(D2,3,2)&":"&MID(D2,5,2)&":"&MID(D2,7,2)&":"&MID(D2,9,2)&":"&RIGHT(D2,2) | H2: 9BD0F696F03648E2 | I2: =IFERROR(_xlfn.IFNA(INDEX(Sensors_MANU!$C$2:$C$4692,MATCH($D2,Sensors_MANU!$B$2:$B$4692,0)),INDEX(Sensors_MANU!$C$2:$C$4692,MATCH($P2,Sensors_MANU!$A$2:$A$4692,0))),"") | J2: =IFERROR(_xlfn.IFNA(INDEX(Sensors_MANU!$D$2:$D$4692,MATCH($D2,Sensors_MANU!$B$2:$B$4692,0)),INDEX(Sensors_MANU!$D$2:$D$4692,MATCH($P2,Sensors_MANU!$A$2:$A$4692,0))),"") | N2: =IFERROR(INDEX(Sensors_MANU!$G$2:$G$4692,MATCH($P2,Sensors_MANU!$A$2:$A$4692,0)),) | O2: v15 | P2: 4978893
A3: =IFERROR(_xlfn.IFNA(INDEX(Sensors_MANU!$E$2:$E$4692,MATCH($D3,Sensors_MANU!$B$2:$B$4692,0)),INDEX(Sensors_MANU!$E$2:$E$4692,MATCH($P3,Sensors_MANU!$A$2:$A$4692,0))),"") | B3: =IFERROR(INDEX(Companies!$A$3:$A$101,MATCH(A3,Companies!$B$3:$B$101,0)),"") | C3: cargo | D3: F5E6900F2468 | E3: =LEFT(D3,2)&":"&MID(D3,3,2)&":"&MID(D3,5,2)&":"&MID(D3,7,2)&":"&MID(D3,9,2)&":"&RIGHT(D3,2) | H3: 6A15C584C8CFC67E | I3: =IFERROR(_xlfn.IFNA(INDEX(Sensors_MANU!$C$2:$C$4692,MATCH($D3,Sensors_MANU!$B$2:$B$4692,0)),INDEX(Sensors_MANU!$C$2:$C$4692,MATCH($P3,Sensors_MANU!$A$2:$A$4692,0))),"") | J3: =IFERROR(_xlfn.IFNA(INDEX(Sensors_MANU!$D$2:$D$4692,MATCH($D3,Sensors_MANU!$B$2:$B$4692,0)),INDEX(Sensors_MANU!$D$2:$D$4692,MATCH($P3,Sensors_MANU!$A$2:$A$4692,0))),"") | N3: =IFERROR(INDEX(Sensors_MANU!$G$2:$G$4692,MATCH($P3,Sensors_MANU!$A$2:$A$4692,0)),) | O3: v15 | P3: 4978559
A4: =IFERROR(_xlfn.IFNA(INDEX(Sensors_MANU!$E$2:$E$4692,MATCH($D4,Sensors_MANU!$B$2:$B$4692,0)),INDEX(Sensors_MANU!$E$2:$E$4692,MATCH($P4,Sensors_MANU!$A$2:$A$4692,0))),"") | B4: =IFERROR(INDEX(Companies!$A$3:$A$101,MATCH(A4,Companies!$B$3:$B$101,0)),"") | C4: =IFERROR(_xlfn.IFNA(INDEX(Sensors_MANU!$F$2:$F$4692,MATCH($D4,Sensors_MANU!$B$2:$B$4692,0)),INDEX(Sensors_MANU!$F$2:$F$4692,MATCH($P4,Sensors_MANU!$A$2:$A$4692,0))),"") | D4: CCBE92DDADA2 | E4: =LEFT(D4,2)&":"&MID(D4,3,2)&":"&MID(D4,5,2)&":"&MID(D4,7,2)&":"&MID(D4,9,2)&":"&RIGHT(D4,2) | H4: 3104D52E64F6BC42 | I4: =IFERROR(_xlfn.IFNA(INDEX(Sensors_MANU!$C$2:$C$4692,MATCH($D4,Sensors_MANU!$B$2:$B$4692,0)),INDEX(Sensors_MANU!$C$2:$C$4692,MATCH($P4,Sensors_MANU!$A$2:$A$4692,0))),"") | J4: =IFERROR(_xlfn.IFNA(INDEX(Sensors_MANU!$D$2:$D$4692,MATCH($D4,Sensors_MANU!$B$2:$B$4692,0)),INDEX(Sensors_MANU!$D$2:$D$4692,MATCH($P4,Sensors_MANU!$A$2:$A$4692,0))),"") | N4: =IFERROR(INDEX(Sensors_MANU!$G$2:$G$4692,MATCH($P4,Sensors_MANU!$A$2:$A$4692,0)),) | O4: v16 | P4: 4978760
A5: =IFERROR(_xlfn.IFNA(INDEX(Sensors_MANU!$E$2:$E$4692,MATCH($D5,Sensors_MANU!$B$2:$B$4692,0)),INDEX(Sensors_MANU!$E$2:$E$4692,MATCH($P5,Sensors_MANU!$A$2:$A$4692,0))),"") | B5: =IFERROR(INDEX(Companies!$A$3:$A$101,MATCH(A5,Companies!$B$3:$B$101,0)),"") | C5: =IFERROR(_xlfn.IFNA(INDEX(Sensors_MANU!$F$2:$F$4692,MATCH($D5,Sensors_MANU!$B$2:$B$4692,0)),INDEX(Sensors_MANU!$F$2:$F$4692,MATCH($P5,Sensors_MANU!$A$2:$A$4692,0))),"") | D5: EBDBAF70D5EB | E5: =LEFT(D5,2)&":"&MID(D5,3,2)&":"&MID(D5,5,2)&":"&MID(D5,7,2)&":"&MID(D5,9,2)&":"&RIGHT(D5,2) | H5: A77AFEC1B85B62CA | I5: =IFERROR(_xlfn.IFNA(INDEX(Sensors_MANU!$C$2:$C$4692,MATCH($D5,Sensors_MANU!$B$2:$B$4692,0)),INDEX(Sensors_MANU!$C$2:$C$4692,MATCH($P5,Sensors_MANU!$A$2:$A$4692,0))),"") | J5: =IFERROR(_xlfn.IFNA(INDEX(Sensors_MANU!$D$2:$D$4692,MATCH($D5,Sensors_MANU!$B$2:$B$4692,0)),INDEX(Sensors_MANU!$D$2:$D$4692,MATCH($P5,Sensors_MANU!$A$2:$A$4692,0))),"") | N5: =IFERROR(INDEX(Sensors_MANU!$G$2:$G$4692,MATCH($P5,Sensors_MANU!$A$2:$A$4692,0)),) | O5: v16 | P5: 4978894
A6: =IFERROR(_xlfn.IFNA(INDEX(Sensors_MANU!$E$2:$E$4692,MATCH($D6,Sensors_MANU!$B$2:$B$4692,0)),INDEX(Sensors_MANU!$E$2:$E$4692,MATCH($P6,Sensors_MANU!$A$2:$A$4692,0))),"") | B6: =IFERROR(INDEX(Companies!$A$3:$A$101,MATCH(A6,Companies!$B$3:$B$101,0)),"") | C6: =IFERROR(_xlfn.IFNA(INDEX(Sensors_MANU!$F$2:$F$4692,MATCH($D6,Sensors_MANU!$B$2:$B$4692,0)),INDEX(Sensors_MANU!$F$2:$F$4692,MATCH($P6,Sensors_MANU!$A$2:$A$4692,0))),"") | D6: CF346653DE8F | E6: =LEFT(D6,2)&":"&MID(D6,3,2)&":"&MID(D6,5,2)&":"&MID(D6,7,2)&":"&MID(D6,9,2)&":"&RIGHT(D6,2) | H6: B51ED4D08EDB68DC | I6: =IFERROR(_xlfn.IFNA(INDEX(Sensors_MANU!$C$2:$C$4692,MATCH($D6,Sensors_MANU!$B$2:$B$4692,0)),INDEX(Sensors_MANU!$C$2:$C$4692,MATCH($P6,Sensors_MANU!$A$2:$A$4692,0))),"") | J6: =IFERROR(_xlfn.IFNA(INDEX(Sensors_MANU!$D$2:$D$4692,MATCH($D6,Sensors_MANU!$B$2:$B$4692,0)),INDEX(Sensors_MANU!$D$2:$D$4692,MATCH($P6,Sensors_MANU!$A$2:$A$4692,0))),"") | N6: =IFERROR(INDEX(Sensors_MANU!$G$2:$G$4692,MATCH($P6,Sensors_MANU!$A$2:$A$4692,0)),) | O6: v16 | P6: 4978736
A7: =IFERROR(_xlfn.IFNA(INDEX(Sensors_MANU!$E$2:$E$4692,MATCH($D7,Sensors_MANU!$B$2:$B$4692,0)),INDEX(Sensors_MANU!$E$2:$E$4692,MATCH($P7,Sensors_MANU!$A$2:$A$4692,0))),"") | B7: =IFERROR(INDEX(Companies!$A$3:$A$101,MATCH(A7,Companies!$B$3:$B$101,0)),"") | C7: =IFERROR(_xlfn.IFNA(INDEX(Sensors_MANU!$F$2:$F$4692,MATCH($D7,Sensors_MANU!$B$2:$B$4692,0)),INDEX(Sensors_MANU!$F$2:$F$4692,MATCH($P7,Sensors_MANU!$A$2:$A$4692,0))),"") | D7: C14457685970 | E7: =LEFT(D7,2)&":"&MID(D7,3,2)&":"&MID(D7,5,2)&":"&MID(D7,7,2)&":"&MID(D7,9,2)&":"&RIGHT(D7,2) | H7: 44C642BFEA2ABC0F | I7: =IFERROR(_xlfn.IFNA(INDEX(Sensors_MANU!$C$2:$C$4692,MATCH($D7,Sensors_MANU!$B$2:$B$4692,0)),INDEX(Sensors_MANU!$C$2:$C$4692,MATCH($P7,Sensors_MANU!$A$2:$A$4692,0))),"") | J7: =IFERROR(_xlfn.IFNA(INDEX(Sensors_MANU!$D$2:$D$4692,MATCH($D7,Sensors_MANU!$B$2:$B$4692,0)),INDEX(Sensors_MANU!$D$2:$D$4692,MATCH($P7,Sensors_MANU!$A$2:$A$4692,0))),"") | N7: =IFERROR(INDEX(Sensors_MANU!$G$2:$G$4692,MATCH($P7,Sensors_MANU!$A$2:$A$4692,0)),) | O7: v16 | P7: 4978852
A8: =IFERROR(_xlfn.IFNA(INDEX(Sensors_MANU!$E$2:$E$4692,MATCH($D8,Sensors_MANU!$B$2:$B$4692,0)),INDEX(Sensors_MANU!$E$2:$E$4692,MATCH($P8,Sensors_MANU!$A$2:$A$4692,0))),"") | B8: =IFERROR(INDEX(Companies!$A$3:$A$101,MATCH(A8,Companies!$B$3:$B$101,0)),"") | C8: cargo | D8: E52691E7E135 | E8: =LEFT(D8,2)&":"&MID(D8,3,2)&":"&MID(D8,5,2)&":"&MID(D8,7,2)&":"&MID(D8,9,2)&":"&RIGHT(D8,2) | H8: 4DAFD62AFA537A1A | I8: =IFERROR(_xlfn.IFNA(INDEX(Sensors_MANU!$C$2:$C$4692,MATCH($D8,Sensors_MANU!$B$2:$B$4692,0)),INDEX(Sensors_MANU!$C$2:$C$4692,MATCH($P8,Sensors_MANU!$A$2:$A$4692,0))),"") | J8: =IFERROR(_xlfn.IFNA(INDEX(Sensors_MANU!$D$2:$D$4692,MATCH($D8,Sensors_MANU!$B$2:$B$4692,0)),INDEX(Sensors_MANU!$D$2:$D$4692,MATCH($P8,Sensors_MANU!$A$2:$A$4692,0))),"") | N8: =IFERROR(INDEX(Sensors_MANU!$G$2:$G$4692,MATCH($P8,Sensors_MANU!$A$2:$A$4692,0)),) | O8: v17 | P8: 4978898
A9: =IFERROR(_xlfn.IFNA(INDEX(Sensors_MANU!$E$2:$E$4692,MATCH($D9,Sensors_MANU!$B$2:$B$4692,0)),INDEX(Sensors_MANU!$E$2:$E$4692,MATCH($P9,Sensors_MANU!$A$2:$A$4692,0))),"") | B9: =IFERROR(INDEX(Companies!$A$3:$A$101,MATCH(A9,Companies!$B$3:$B$101,0)),"") | C9: =IFERROR(_xlfn.IFNA(INDEX(Sensors_MANU!$F$2:$F$4692,MATCH($D9,Sensors_MANU!$B$2:$B$4692,0)),INDEX(Sensors_MANU!$F$2:$F$4692,MATCH($P9,Sensors_MANU!$A$2:$A$4692,0))),"") | D9: C2E36726A269 | E9: =LEFT(D9,2)&":"&MID(D9,3,2)&":"&MID(D9,5,2)&":"&MID(D9,7,2)&":"&MID(D9,9,2)&":"&RIGHT(D9,2) | H9: 0FEFDF4A53CF11E7 | I9: =IFERROR(_xlfn.IFNA(INDEX(Sensors_MANU!$C$2:$C$4692,MATCH($D9,Sensors_MANU!$B$2:$B$4692,0)),INDEX(Sensors_MANU!$C$2:$C$4692,MATCH($P9,Sensors_MANU!$A$2:$A$4692,0))),"") | J9: =IFERROR(_xlfn.IFNA(INDEX(Sensors_MANU!$D$2:$D$4692,MATCH($D9,Sensors_MANU!$B$2:$B$4692,0)),INDEX(Sensors_MANU!$D$2:$D$4692,MATCH($P9,Sensors_MANU!$A$2:$A$4692,0))),"") | N9: =IFERROR(INDEX(Sensors_MANU!$G$2:$G$4692,MATCH($P9,Sensors_MANU!$A$2:$A$4692,0)),) | O9: v16 | P9: 4978458
A10: =IFERROR(_xlfn.IFNA(INDEX(Sensors_MANU!$E$2:$E$4692,MATCH($D10,Sensors_MANU!$B$2:$B$4692,0)),INDEX(Sensors_MANU!$E$2:$E$4692,MATCH($P10,Sensors_MANU!$A$2:$A$4692,0))),"") | B10: =IFERROR(INDEX(Companies!$A$3:$A$101,MATCH(A10,Companies!$B$3:$B$101,0)),"") | C10: =IFERROR(_xlfn.IFNA(INDEX(Sensors_MANU!$F$2:$F$4692,MATCH($D10,Sensors_MANU!$B$2:$B$4692,0)),INDEX(Sensors_MANU!$F$2:$F$4692,MATCH($P10,Sensors_MANU!$A$2:$A$4692,0))),"") | D10: F63EB7585D0D | E10: =LEFT(D10,2)&":"&MID(D10,3,2)&":"&MID(D10,5,2)&":"&MID(D10,7,2)&":"&MID(D10,9,2)&":"&RIGHT(D10,2) | H10: 08120EAEC72814BB | I10: =IFERROR(_xlfn.IFNA(INDEX(Sensors_MANU!$C$2:$C$4692,MATCH($D10,Sensors_MANU!$B$2:$B$4692,0)),INDEX(Sensors_MANU!$C$2:$C$4692,MATCH($P10,Sensors_MANU!$A$2:$A$4692,0))),"") | J10: =IFERROR(_xlfn.IFNA(INDEX(Sensors_MANU!$D$2:$D$4692,MATCH($D10,Sensors_MANU!$B$2:$B$4692,0)),INDEX(Sensors_MANU!$D$2:$D$4692,MATCH($P10,Sensors_MANU!$A$2:$A$4692,0))),"") | N10: =IFERROR(INDEX(Sensors_MANU!$G$2:$G$4692,MATCH($P10,Sensors_MANU!$A$2:$A$4692,0)),) | O10: v16 | P10: 4978427
A11: =IFERROR(_xlfn.IFNA(INDEX(Sensors_MANU!$E$2:$E$4692,MATCH($D11,Sensors_MANU!$B$2:$B$4692,0)),INDEX(Sensors_MANU!$E$2:$E$4692,MATCH($P11,Sensors_MANU!$A$2:$A$4692,0))),"") | B11: =IFERROR(INDEX(Companies!$A$3:$A$101,MATCH(A11,Companies!$B$3:$B$101,0)),"") | C11: =IFERROR(_xlfn.IFNA(INDEX(Sensors_MANU!$F$2:$F$4692,MATCH($D11,Sensors_MANU!$B$2:$B$4692,0)),INDEX(Sensors_MANU!$F$2:$F$4692,MATCH($P11,Sensors_MANU!$A$2:$A$4692,0))),"") | D11: CE2347DA87C2 | E11: =LEFT(D11,2)&":"&MID(D11,3,2)&":"&MID(D11,5,2)&":"&MID(D11,7,2)&":"&MID(D11,9,2)&":"&RIGHT(D11,2) | H11: 617AAC9DE1DE16E0 | I11: =IFERROR(_xlfn.IFNA(INDEX(Sensors_MANU!$C$2:$C$4692,MATCH($D11,Sensors_MANU!$B$2:$B$4692,0)),INDEX(Sensors_MANU!$C$2:$C$4692,MATCH($P11,Sensors_MANU!$A$2:$A$4692,0))),"") | J11: =IFERROR(_xlfn.IFNA(INDEX(Sensors_MANU!$D$2:$D$4692,MATCH($D11,Sensors_MANU!$B$2:$B$4692,0)),INDEX(Sensors_MANU!$D$2:$D$4692,MATCH($P11,Sensors_MANU!$A$2:$A$4692,0))),"") | N11: =IFERROR(INDEX(Sensors_MANU!$G$2:$G$4692,MATCH($P11,Sensors_MANU!$A$2:$A$4692,0)),) | O11: v16 | P11: 4978434
A12: =IFERROR(_xlfn.IFNA(INDEX(Sensors_MANU!$E$2:$E$4692,MATCH($D12,Sensors_MANU!$B$2:$B$4692,0)),INDEX(Sensors_MANU!$E$2:$E$4692,MATCH($P12,Sensors_MANU!$A$2:$A$4692,0))),"") | B12: =IFERROR(INDEX(Companies!$A$3:$A$101,MATCH(A12,Companies!$B$3:$B$101,0)),"") | C12: =IFERROR(_xlfn.IFNA(INDEX(Sensors_MANU!$F$2:$F$4692,MATCH($D12,Sensors_MANU!$B$2:$B$4692,0)),INDEX(Sensors_MANU!$F$2:$F$4692,MATCH($P12,Sensors_MANU!$A$2:$A$4692,0))),"") | D12: E090C924055C | E12: =LEFT(D12,2)&":"&MID(D12,3,2)&":"&MID(D12,5,2)&":"&MID(D12,7,2)&":"&MID(D12,9,2)&":"&RIGHT(D12,2) | H12: 29B29DC69DC3E110 | I12: =IFERROR(_xlfn.IFNA(INDEX(Sensors_MANU!$C$2:$C$4692,MATCH($D12,Sensors_MANU!$B$2:$B$4692,0)),INDEX(Sensors_MANU!$C$2:$C$4692,MATCH($P12,Sensors_MANU!$A$2:$A$4692,0))),"") | J12: =IFERROR(_xlfn.IFNA(INDEX(Sensors_MANU!$D$2:$D$4692,MATCH($D12,Sensors_MANU!$B$2:$B$4692,0)),INDEX(Sensors_MANU!$D$2:$D$4692,MATCH($P12,Sensors_MANU!$A$2:$A$4692,0))),"") | N12: =IFERROR(INDEX(Sensors_MANU!$G$2:$G$4692,MATCH($P12,Sensors_MANU!$A$2:$A$4692,0)),) | O12: v16 | P12: 4978463
A13: =IFERROR(_xlfn.IFNA(INDEX(Sensors_MANU!$E$2:$E$4692,MATCH($D13,Sensors_MANU!$B$2:$B$4692,0)),INDEX(Sensors_MANU!$E$2:$E$4692,MATCH($P13,Sensors_MANU!$A$2:$A$4692,0))),"") | B13: =IFERROR(INDEX(Companies!$A$3:$A$101,MATCH(A13,Companies!$B$3:$B$101,0)),"") | C13: =IFERROR(_xlfn.IFNA(INDEX(Sensors_MANU!$F$2:$F$4692,MATCH($D13,Sensors_MANU!$B$2:$B$4692,0)),INDEX(Sensors_MANU!$F$2:$F$4692,MATCH($P13,Sensors_MANU!$A$2:$A$4692,0))),"") | D13: D6D2AF577A5F | E13: =LEFT(D13,2)&":"&MID(D13,3,2)&":"&MID(D13,5,2)&":"&MID(D13,7,2)&":"&MID(D13,9,2)&":"&RIGHT(D13,2) | H13: A7B964273F9D1E7F | I13: =IFERROR(_xlfn.IFNA(INDEX(Sensors_MANU!$C$2:$C$4692,MATCH($D13,Sensors_MANU!$B$2:$B$4692,0)),INDEX(Sensors_MANU!$C$2:$C$4692,MATCH($P13,Sensors_MANU!$A$2:$A$4692,0))),"") | J13: =IFERROR(_xlfn.IFNA(INDEX(Sensors_MANU!$D$2:$D$4692,MATCH($D13,Sensors_MANU!$B$2:$B$4692,0)),INDEX(Sensors_MANU!$D$2:$D$4692,MATCH($P13,Sensors_MANU!$A$2:$A$4692,0))),"") | N13: =IFERROR(INDEX(Sensors_MANU!$G$2:$G$4692,MATCH($P13,Sensors_MANU!$A$2:$A$4692,0)),) | O13: v16 | P13: 4978426
A14: =IFERROR(_xlfn.IFNA(INDEX(Sensors_MANU!$E$2:$E$4692,MATCH($D14,Sensors_MANU!$B$2:$B$4692,0)),INDEX(Sensors_MANU!$E$2:$E$4692,MATCH($P14,Sensors_MANU!$A$2:$A$4692,0))),"") | B14: =IFERROR(INDEX(Companies!$A$3:$A$101,MATCH(A14,Companies!$B$3:$B$101,0)),"") | C14: =IFERROR(_xlfn.IFNA(INDEX(Sensors_MANU!$F$2:$F$4692,MATCH($D14,Sensors_MANU!$B$2:$B$4692,0)),INDEX(Sensors_MANU!$F$2:$F$4692,MATCH($P14,Sensors_MANU!$A$2:$A$4692,0))),"") | D14: F51EBDF99D9C | E14: =LEFT(D14,2)&":"&MID(D14,3,2)&":"&MID(D14,5,2)&":"&MID(D14,7,2)&":"&MID(D14,9,2)&":"&RIGHT(D14,2) | H14: 451627EFB4767859 | I14: =IFERROR(_xlfn.IFNA(INDEX(Sensors_MANU!$C$2:$C$4692,MATCH($D14,Sensors_MANU!$B$2:$B$4692,0)),INDEX(Sensors_MANU!$C$2:$C$4692,MATCH($P14,Sensors_MANU!$A$2:$A$4692,0))),"") | J14: =IFERROR(_xlfn.IFNA(INDEX(Sensors_MANU!$D$2:$D$4692,MATCH($D14,Sensors_MANU!$B$2:$B$4692,0)),INDEX(Sensors_MANU!$D$2:$D$4692,MATCH($P14,Sensors_MANU!$A$2:$A$4692,0))),"") | N14: can be 410 | O14: v16 | P14: 4978885-1
A15: LTG | B15: =IFERROR(INDEX(Companies!$A$3:$A$101,MATCH(A15,Companies!$B$3:$B$101,0)),"") | C15: cargo | D15: CA47C040C433 | E15: =LEFT(D15,2)&":"&MID(D15,3,2)&":"&MID(D15,5,2)&":"&MID(D15,7,2)&":"&MID(D15,9,2)&":"&RIGHT(D15,2) | H15: 3195A8F0F36AE326 | J15: =IFERROR(_xlfn.IFNA(INDEX(Sensors_MANU!$D$2:$D$4692,MATCH($D15,Sensors_MANU!$B$2:$B$4692,0)),INDEX(Sensors_MANU!$D$2:$D$4692,MATCH($P15,Sensors_MANU!$A$2:$A$4692,0))),"") | N15: =IFERROR(INDEX(Sensors_MANU!$G$2:$G$4692,MATCH($P15,Sensors_MANU!$A$2:$A$4692,0)),) | O15: v14
A16: LTG | B16: =IFERROR(INDEX(Companies!$A$3:$A$101,MATCH(A16,Companies!$B$3:$B$101,0)),"") | C16: cargo | D16: C08CFD293A0B | E16: =LEFT(D16,2)&":"&MID(D16,3,2)&":"&MID(D16,5,2)&":"&MID(D16,7,2)&":"&MID(D16,9,2)&":"&RIGHT(D16,2) | H16: B1D7F63C53732A72 | J16: =IFERROR(_xlfn.IFNA(INDEX(Sensors_MANU!$D$2:$D$4692,MATCH($D16,Sensors_MANU!$B$2:$B$4692,0)),INDEX(Sensors_MANU!$D$2:$D$4692,MATCH($P16,Sensors_MANU!$A$2:$A$4692,0))),"") | N16: =IFERROR(INDEX(Sensors_MANU!$G$2:$G$4692,MATCH($P16,Sensors_MANU!$A$2:$A$4692,0)),) | O16: v14
A17: LTG | B17: =IFERROR(INDEX(Companies!$A$3:$A$101,MATCH(A17,Companies!$B$3:$B$101,0)),"") | C17: cargo | D17: EF9AFE3E365F | E17: =LEFT(D17,2)&":"&MID(D17,3,2)&":"&MID(D17,5,2)&":"&MID(D17,7,2)&":"&MID(D17,9,2)&":"&RIGHT(D17,2) | H17: F4E2E2C6AA67ABB4 | J17: =IFERROR(_xlfn.IFNA(INDEX(Sensors_MANU!$D$2:$D$4692,MATCH($D17,Sensors_MANU!$B$2:$B$4692,0)),INDEX(Sensors_MANU!$D$2:$D$4692,MATCH($P17,Sensors_MANU!$A$2:$A$4692,0))),"") | N17: =IFERROR(INDEX(Sensors_MANU!$G$2:$G$4692,MATCH($P17,Sensors_MANU!$A$2:$A$4692,0)),) | O17: v14
A18: LTG | B18: =IFERROR(INDEX(Companies!$A$3:$A$101,MATCH(A18,Companies!$B$3:$B$101,0)),"") | C18: cargo | D18: E36493AD4D8A | E18: =LEFT(D18,2)&":"&MID(D18,3,2)&":"&MID(D18,5,2)&":"&MID(D18,7,2)&":"&MID(D18,9,2)&":"&RIGHT(D18,2) | H18: 796068D2E9ADC10E | J18: =IFERROR(_xlfn.IFNA(INDEX(Sensors_MANU!$D$2:$D$4692,MATCH($D18,Sensors_MANU!$B$2:$B$4692,0)),INDEX(Sensors_MANU!$D$2:$D$4692,MATCH($P18,Sensors_MANU!$A$2:$A$4692,0))),"") | N18: =IFERROR(INDEX(Sensors_MANU!$G$2:$G$4692,MATCH($P18,Sensors_MANU!$A$2:$A$4692,0)),) | O18: v14
A19: LTG | B19: =IFERROR(INDEX(Companies!$A$3:$A$101,MATCH(A19,Companies!$B$3:$B$101,0)),"") | C19: cargo | D19: DF84A361C71F | E19: =LEFT(D19,2)&":"&MID(D19,3,2)&":"&MID(D19,5,2)&":"&MID(D19,7,2)&":"&MID(D19,9,2)&":"&RIGHT(D19,2) | H19: 44FE153166EE19D3 | J19: =IFERROR(_xlfn.IFNA(INDEX(Sensors_MANU!$D$2:$D$4692,MATCH($D19,Sensors_MANU!$B$2:$B$4692,0)),INDEX(Sensors_MANU!$D$2:$D$4692,MATCH($P19,Sensors_MANU!$A$2:$A$4692,0))),"") | N19: =IFERROR(INDEX(Sensors_MANU!$G$2:$G$4692,MATCH($P19,Sensors_MANU!$A$2:$A$4692,0)),) | O19: v14
A20: LTG | B20: =IFERROR(INDEX(Companies!$A$3:$A$101,MATCH(A20,Companies!$B$3:$B$101,0)),"") | C20: cargo | D20: C9FADA90E01A | E20: =LEFT(D20,2)&":"&MID(D20,3,2)&":"&MID(D20,5,2)&":"&MID(D20,7,2)&":"&MID(D20,9,2)&":"&RIGHT(D20,2) | H20: FA55DC7FE24221A5 | J20: =IFERROR(_xlfn.IFNA(INDEX(Sensors_MANU!$D$2:$D$4692,MATCH($D20,Sensors_MANU!$B$2:$B$4692,0)),INDEX(Sensors_MANU!$D$2:$D$4692,MATCH($P20,Sensors_MANU!$A$2:$A$4692,0))),"") | N20: =IFERROR(INDEX(Sensors_MANU!$G$2:$G$4692,MATCH($P20,Sensors_MANU!$A$2:$A$4692,0)),) | O20: v14
A21: LTG | B21: =IFERROR(INDEX(Companies!$A$3:$A$101,MATCH(A21,Companies!$B$3:$B$101,0)),"") | C21: cargo | D21: FED5B1121159 | E21: =LEFT(D21,2)&":"&MID(D21,3,2)&":"&MID(D21,5,2)&":"&MID(D21,7,2)&":"&MID(D21,9,2)&":"&RIGHT(D21,2) | H21: 3D56D82F3CE320DC | J21: =IFERROR(_xlfn.IFNA(INDEX(Sensors_MANU!$D$2:$D$4692,MATCH($D21,Sensors_MANU!$B$2:$B$4692,0)),INDEX(Sensors_MANU!$D$2:$D$4692,MATCH($P21,Sensors_MANU!$A$2:$A$4692,0))),"") | N21: =IFERROR(INDEX(Sensors_MANU!$G$2:$G$4692,MATCH($P21,Sensors_MANU!$A$2:$A$4692,0)),) | O21: v14
A22: LTG | B22: =IFERROR(INDEX(Companies!$A$3:$A$101,MATCH(A22,Companies!$B$3:$B$101,0)),"") | C22: cargo | D22: F4A0AC714AF7 | E22: =LEFT(D22,2)&":"&MID(D22,3,2)&":"&MID(D22,5,2)&":"&MID(D22,7,2)&":"&MID(D22,9,2)&":"&RIGHT(D22,2) | H22: 1E21F89A9486812F | J22: =IFERROR(_xlfn.IFNA(INDEX(Sensors_MANU!$D$2:$D$4692,MATCH($D22,Sensors_MANU!$B$2:$B$4692,0)),INDEX(Sensors_MANU!$D$2:$D$4692,MATCH($P22,Sensors_MANU!$A$2:$A$4692,0))),"") | N22: =IFERROR(INDEX(Sensors_MANU!$G$2:$G$4692,MATCH($P22,Sensors_MANU!$A$2:$A$4692,0)),) | O22: v14
A23: =IFERROR(_xlfn.IFNA(INDEX(Sensors_MANU!$E$2:$E$4692,MATCH($D23,Sensors_MANU!$B$2:$B$4692,0)),INDEX(Sensors_MANU!$E$2:$E$4692,MATCH($P23,Sensors_MANU!$A$2:$A$4692,0))),"") | B23: =IFERROR(INDEX(Companies!$A$3:$A$101,MATCH(A23,Companies!$B$3:$B$101,0)),"") | C23: =IFERROR(_xlfn.IFNA(INDEX(Sensors_MANU!$F$2:$F$4692,MATCH($D23,Sensors_MANU!$B$2:$B$4692,0)),INDEX(Sensors_MANU!$F$2:$F$4692,MATCH($P23,Sensors_MANU!$A$2:$A$4692,0))),"") | D23: DF5840FDF698 | E23: =LEFT(D23,2)&":"&MID(D23,3,2)&":"&MID(D23,5,2)&":"&MID(D23,7,2)&":"&MID(D23,9,2)&":"&RIGHT(D23,2) | H23: C56ABA8666D8307F | I23: =IFERROR(_xlfn.IFNA(INDEX(Sensors_MANU!$C$2:$C$4692,MATCH($D23,Sensors_MANU!$B$2:$B$4692,0)),INDEX(Sensors_MANU!$C$2:$C$4692,MATCH($P23,Sensors_MANU!$A$2:$A$4692,0))),"") | J23: =IFERROR(_xlfn.IFNA(INDEX(Sensors_MANU!$D$2:$D$4692,MATCH($D23,Sensors_MANU!$B$2:$B$4692,0)),INDEX(Sensors_MANU!$D$2:$D$4692,MATCH($P23,Sensors_MANU!$A$2:$A$4692,0))),"") | N23: Not in Pacific (in Viezo office) | O23: v16 | P23: 4978662
A24: =IFERROR(_xlfn.IFNA(INDEX(Sensors_MANU!$E$2:$E$4692,MATCH($D24,Sensors_MANU!$B$2:$B$4692,0)),INDEX(Sensors_MANU!$E$2:$E$4692,MATCH($P24,Sensors_MANU!$A$2:$A$4692,0))),"") | B24: =IFERROR(INDEX(Companies!$A$3:$A$101,MATCH(A24,Companies!$B$3:$B$101,0)),"") | C24: =IFERROR(_xlfn.IFNA(INDEX(Sensors_MANU!$F$2:$F$4692,MATCH($D24,Sensors_MANU!$B$2:$B$4692,0)),INDEX(Sensors_MANU!$F$2:$F$4692,MATCH($P24,Sensors_MANU!$A$2:$A$4692,0))),"") | D24: C22B286A9D62 | E24: =LEFT(D24,2)&":"&MID(D24,3,2)&":"&MID(D24,5,2)&":"&MID(D24,7,2)&":"&MID(D24,9,2)&":"&RIGHT(D24,2) | H24: 2B0BFB663293135A | I24: =IFERROR(_xlfn.IFNA(INDEX(Sensors_MANU!$C$2:$C$4692,MATCH($D24,Sensors_MANU!$B$2:$B$4692,0)),INDEX(Sensors_MANU!$C$2:$C$4692,MATCH($P24,Sensors_MANU!$A$2:$A$4692,0))),"") | J24: =IFERROR(_xlfn.IFNA(INDEX(Sensors_MANU!$D$2:$D$4692,MATCH($D24,Sensors_MANU!$B$2:$B$4692,0)),INDEX(Sensors_MANU!$D$2:$D$4692,MATCH($P24,Sensors_MANU!$A$2:$A$4692,0))),"") | N24: =IFERROR(INDEX(Sensors_MANU!$G$2:$G$4692,MATCH($P24,Sensors_MANU!$A$2:$A$4692,0)),) | O24: v17 | P24: 4978664
A25: =IFERROR(_xlfn.IFNA(INDEX(Sensors_MANU!$E$2:$E$4692,MATCH($D25,Sensors_MANU!$B$2:$B$4692,0)),INDEX(Sensors_MANU!$E$2:$E$4692,MATCH($P25,Sensors_MANU!$A$2:$A$4692,0))),"") | B25: =IFERROR(INDEX(Companies!$A$3:$A$101,MATCH(A25,Companies!$B$3:$B$101,0)),"") | C25: =IFERROR(_xlfn.IFNA(INDEX(Sensors_MANU!$F$2:$F$4692,MATCH($D25,Sensors_MANU!$B$2:$B$4692,0)),INDEX(Sensors_MANU!$F$2:$F$4692,MATCH($P25,Sensors_MANU!$A$2:$A$4692,0))),"") | D25: C6CE395D9E33 | E25: =LEFT(D25,2)&":"&MID(D25,3,2)&":"&MID(D25,5,2)&":"&MID(D25,7,2)&":"&MID(D25,9,2)&":"&RIGHT(D25,2) | H25: 7FB52187268620B1 | I25: =IFERROR(_xlfn.IFNA(INDEX(Sensors_MANU!$C$2:$C$4692,MATCH($D25,Sensors_MANU!$B$2:$B$4692,0)),INDEX(Sensors_MANU!$C$2:$C$4692,MATCH($P25,Sensors_MANU!$A$2:$A$4692,0))),"") | J25: =IFERROR(_xlfn.IFNA(INDEX(Sensors_MANU!$D$2:$D$4692,MATCH($D25,Sensors_MANU!$B$2:$B$4692,0)),INDEX(Sensors_MANU!$D$2:$D$4692,MATCH($P25,Sensors_MANU!$A$2:$A$4692,0))),"") | N25: =IFERROR(INDEX(Sensors_MANU!$G$2:$G$4692,MATCH($P25,Sensors_MANU!$A$2:$A$4692,0)),) | O25: v17 | P25: 4978763
A26: =IFERROR(_xlfn.IFNA(INDEX(Sensors_MANU!$E$2:$E$4692,MATCH($D26,Sensors_MANU!$B$2:$B$4692,0)),INDEX(Sensors_MANU!$E$2:$E$4692,MATCH($P26,Sensors_MANU!$A$2:$A$4692,0))),"") | B26: =IFERROR(INDEX(Companies!$A$3:$A$101,MATCH(A26,Companies!$B$3:$B$101,0)),"") | C26: =IFERROR(_xlfn.IFNA(INDEX(Sensors_MANU!$F$2:$F$4692,MATCH($D26,Sensors_MANU!$B$2:$B$4692,0)),INDEX(Sensors_MANU!$F$2:$F$4692,MATCH($P26,Sensors_MANU!$A$2:$A$4692,0))),"") | D26: F880BAF2AD87 | E26: =LEFT(D26,2)&":"&MID(D26,3,2)&":"&MID(D26,5,2)&":"&MID(D26,7,2)&":"&MID(D26,9,2)&":"&RIGHT(D26,2) | H26: 3342BBBE726B8BA5 | I26: =IFERROR(_xlfn.IFNA(INDEX(Sensors_MANU!$C$2:$C$4692,MATCH($D26,Sensors_MANU!$B$2:$B$4692,0)),INDEX(Sensors_MANU!$C$2:$C$4692,MATCH($P26,Sensors_MANU!$A$2:$A$4692,0))),"") | J26: =IFERROR(_xlfn.IFNA(INDEX(Sensors_MANU!$D$2:$D$4692,MATCH($D26,Sensors_MANU!$B$2:$B$4692,0)),INDEX(Sensors_MANU!$D$2:$D$4692,MATCH($P26,Sensors_MANU!$A$2:$A$4692,0))),"") | N26: =IFERROR(INDEX(Sensors_MANU!$G$2:$G$4692,MATCH($P26,Sensors_MANU!$A$2:$A$4692,0)),) | O26: v17 | P26: 4978607
A27: =IFERROR(_xlfn.IFNA(INDEX(Sensors_MANU!$E$2:$E$4692,MATCH($D27,Sensors_MANU!$B$2:$B$4692,0)),INDEX(Sensors_MANU!$E$2:$E$4692,MATCH($P27,Sensors_MANU!$A$2:$A$4692,0))),"") | B27: =IFERROR(INDEX(Companies!$A$3:$A$101,MATCH(A27,Companies!$B$3:$B$101,0)),"") | C27: =IFERROR(_xlfn.IFNA(INDEX(Sensors_MANU!$F$2:$F$4692,MATCH($D27,Sensors_MANU!$B$2:$B$4692,0)),INDEX(Sensors_MANU!$F$2:$F$4692,MATCH($P27,Sensors_MANU!$A$2:$A$4692,0))),"") | D27: C110C525FA7D | E27: =LEFT(D27,2)&":"&MID(D27,3,2)&":"&MID(D27,5,2)&":"&MID(D27,7,2)&":"&MID(D27,9,2)&":"&RIGHT(D27,2) | H27: 75620B4E10484D4F | I27: =IFERROR(_xlfn.IFNA(INDEX(Sensors_MANU!$C$2:$C$4692,MATCH($D27,Sensors_MANU!$B$2:$B$4692,0)),INDEX(Sensors_MANU!$C$2:$C$4692,MATCH($P27,Sensors_MANU!$A$2:$A$4692,0))),"") | J27: =IFERROR(_xlfn.IFNA(INDEX(Sensors_MANU!$D$2:$D$4692,MATCH($D27,Sensors_MANU!$B$2:$B$4692,0)),INDEX(Sensors_MANU!$D$2:$D$4692,MATCH($P27,Sensors_MANU!$A$2:$A$4692,0))),"") | N27: =IFERROR(INDEX(Sensors_MANU!$G$2:$G$4692,MATCH($P27,Sensors_MANU!$A$2:$A$4692,0)),) | O27: v17 | P27: 4978601
A28: =IFERROR(_xlfn.IFNA(INDEX(Sensors_MANU!$E$2:$E$4692,MATCH($D28,Sensors_MANU!$B$2:$B$4692,0)),INDEX(Sensors_MANU!$E$2:$E$4692,MATCH($P28,Sensors_MANU!$A$2:$A$4692,0))),"") | B28: =IFERROR(INDEX(Companies!$A$3:$A$101,MATCH(A28,Companies!$B$3:$B$101,0)),"") | C28: =IFERROR(_xlfn.IFNA(INDEX(Sensors_MANU!$F$2:$F$4692,MATCH($D28,Sensors_MANU!$B$2:$B$4692,0)),INDEX(Sensors_MANU!$F$2:$F$4692,MATCH($P28,Sensors_MANU!$A$2:$A$4692,0))),"") | D28: DCAF5C3AFCFE | E28: =LEFT(D28,2)&":"&MID(D28,3,2)&":"&MID(D28,5,2)&":"&MID(D28,7,2)&":"&MID(D28,9,2)&":"&RIGHT(D28,2) | H28: 7A2E542E45DA3E34 | I28: =IFERROR(_xlfn.IFNA(INDEX(Sensors_MANU!$C$2:$C$4692,MATCH($D28,Sensors_MANU!$B$2:$B$4692,0)),INDEX(Sensors_MANU!$C$2:$C$4692,MATCH($P28,Sensors_MANU!$A$2:$A$4692,0))),"") | J28: =IFERROR(_xlfn.IFNA(INDEX(Sensors_MANU!$D$2:$D$4692,MATCH($D28,Sensors_MANU!$B$2:$B$4692,0)),INDEX(Sensors_MANU!$D$2:$D$4692,MATCH($P28,Sensors_MANU!$A$2:$A$4692,0))),"") | N28: =IFERROR(INDEX(Sensors_MANU!$G$2:$G$4692,MATCH($P28,Sensors_MANU!$A$2:$A$4692,0)),) | O28: v17 | P28: 4978578
A29: =IFERROR(_xlfn.IFNA(INDEX(Sensors_MANU!$E$2:$E$4692,MATCH($D29,Sensors_MANU!$B$2:$B$4692,0)),INDEX(Sensors_MANU!$E$2:$E$4692,MATCH($P29,Sensors_MANU!$A$2:$A$4692,0))),"") | B29: =IFERROR(INDEX(Companies!$A$3:$A$101,MATCH(A29,Companies!$B$3:$B$101,0)),"") | C29: =IFERROR(_xlfn.IFNA(INDEX(Sensors_MANU!$F$2:$F$4692,MATCH($D29,Sensors_MANU!$B$2:$B$4692,0)),INDEX(Sensors_MANU!$F$2:$F$4692,MATCH($P29,Sensors_MANU!$A$2:$A$4692,0))),"") | D29: DAB5A17D19D0 | E29: =LEFT(D29,2)&":"&MID(D29,3,2)&":"&MID(D29,5,2)&":"&MID(D29,7,2)&":"&MID(D29,9,2)&":"&RIGHT(D29,2) | H29: F16899D9D1554886 | I29: =IFERROR(_xlfn.IFNA(INDEX(Sensors_MANU!$C$2:$C$4692,MATCH($D29,Sensors_MANU!$B$2:$B$4692,0)),INDEX(Sensors_MANU!$C$2:$C$4692,MATCH($P29,Sensors_MANU!$A$2:$A$4692,0))),"") | J29: =IFERROR(_xlfn.IFNA(INDEX(Sensors_MANU!$D$2:$D$4692,MATCH($D29,Sensors_MANU!$B$2:$B$4692,0)),INDEX(Sensors_MANU!$D$2:$D$4692,MATCH($P29,Sensors_MANU!$A$2:$A$4692,0))),"") | O29: V23
A30: =IFERROR(_xlfn.IFNA(INDEX(Sensors_MANU!$E$2:$E$4692,MATCH($D30,Sensors_MANU!$B$2:$B$4692,0)),INDEX(Sensors_MANU!$E$2:$E$4692,MATCH($P30,Sensors_MANU!$A$2:$A$4692,0))),"") | B30: =IFERROR(INDEX(Companies!$A$3:$A$101,MATCH(A30,Companies!$B$3:$B$101,0)),"") | D30: E217C40522CC | E30: =LEFT(D30,2)&":"&MID(D30,3,2)&":"&MID(D30,5,2)&":"&MID(D30,7,2)&":"&MID(D30,9,2)&":"&RIGHT(D30,2) | H30: E00B7A8CCCFEFEF1 | I30: =IFERROR(_xlfn.IFNA(INDEX(Sensors_MANU!$C$2:$C$4692,MATCH($D30,Sensors_MANU!$B$2:$B$4692,0)),INDEX(Sensors_MANU!$C$2:$C$4692,MATCH($P30,Sensors_MANU!$A$2:$A$4692,0))),"") | J30: =IFERROR(_xlfn.IFNA(INDEX(Sensors_MANU!$D$2:$D$4692,MATCH($D30,Sensors_MANU!$B$2:$B$4692,0)),INDEX(Sensors_MANU!$D$2:$D$4692,MATCH($P30,Sensors_MANU!$A$2:$A$4692,0))),"")
A31: =IFERROR(_xlfn.IFNA(INDEX(Sensors_MANU!$E$2:$E$4692,MATCH($D31,Sensors_MANU!$B$2:$B$4692,0)),INDEX(Sensors_MANU!$E$2:$E$4692,MATCH($P31,Sensors_MANU!$A$2:$A$4692,0))),"") | B31: =IFERROR(INDEX(Companies!$A$3:$A$101,MATCH(A31,Companies!$B$3:$B$101,0)),"") | D31: EC21D1AE4CBA | E31: =LEFT(D31,2)&":"&MID(D31,3,2)&":"&MID(D31,5,2)&":"&MID(D31,7,2)&":"&MID(D31,9,2)&":"&RIGHT(D31,2) | H31: 23366BFA23259D4A | I31: =IFERROR(_xlfn.IFNA(INDEX(Sensors_MANU!$C$2:$C$4692,MATCH($D31,Sensors_MANU!$B$2:$B$4692,0)),INDEX(Sensors_MANU!$C$2:$C$4692,MATCH($P31,Sensors_MANU!$A$2:$A$4692,0))),"") | J31: =IFERROR(_xlfn.IFNA(INDEX(Sensors_MANU!$D$2:$D$4692,MATCH($D31,Sensors_MANU!$B$2:$B$4692,0)),INDEX(Sensors_MANU!$D$2:$D$4692,MATCH($P31,Sensors_MANU!$A$2:$A$4692,0))),"")
A32: =IFERROR(_xlfn.IFNA(INDEX(Sensors_MANU!$E$2:$E$4692,MATCH($D32,Sensors_MANU!$B$2:$B$4692,0)),INDEX(Sensors_MANU!$E$2:$E$4692,MATCH($P32,Sensors_MANU!$A$2:$A$4692,0))),"") | B32: =IFERROR(INDEX(Companies!$A$3:$A$101,MATCH(A32,Companies!$B$3:$B$101,0)),"") | D32: D251871CF673 | E32: =LEFT(D32,2)&":"&MID(D32,3,2)&":"&MID(D32,5,2)&":"&MID(D32,7,2)&":"&MID(D32,9,2)&":"&RIGHT(D32,2) | H32: 8C043B92775BEFF8 | I32: =IFERROR(_xlfn.IFNA(INDEX(Sensors_MANU!$C$2:$C$4692,MATCH($D32,Sensors_MANU!$B$2:$B$4692,0)),INDEX(Sensors_MANU!$C$2:$C$4692,MATCH($P32,Sensors_MANU!$A$2:$A$4692,0))),"") | J32: =IFERROR(_xlfn.IFNA(INDEX(Sensors_MANU!$D$2:$D$4692,MATCH($D32,Sensors_MANU!$B$2:$B$4692,0)),INDEX(Sensors_MANU!$D$2:$D$4692,MATCH($P32,Sensors_MANU!$A$2:$A$4692,0))),"")
A33: =IFERROR(_xlfn.IFNA(INDEX(Sensors_MANU!$E$2:$E$4692,MATCH($D33,Sensors_MANU!$B$2:$B$4692,0)),INDEX(Sensors_MANU!$E$2:$E$4692,MATCH($P33,Sensors_MANU!$A$2:$A$4692,0))),"") | B33: =IFERROR(INDEX(Companies!$A$3:$A$101,MATCH(A33,Companies!$B$3:$B$101,0)),"") | D33: E4202FC02258 | E33: =LEFT(D33,2)&":"&MID(D33,3,2)&":"&MID(D33,5,2)&":"&MID(D33,7,2)&":"&MID(D33,9,2)&":"&RIGHT(D33,2) | H33: D4E30509D3A93139 | I33: =IFERROR(_xlfn.IFNA(INDEX(Sensors_MANU!$C$2:$C$4692,MATCH($D33,Sensors_MANU!$B$2:$B$4692,0)),INDEX(Sensors_MANU!$C$2:$C$4692,MATCH($P33,Sensors_MANU!$A$2:$A$4692,0))),"") | J33: =IFERROR(_xlfn.IFNA(INDEX(Sensors_MANU!$D$2:$D$4692,MATCH($D33,Sensors_MANU!$B$2:$B$4692,0)),INDEX(Sensors_MANU!$D$2:$D$4692,MATCH($P33,Sensors_MANU!$A$2:$A$4692,0))),"")
A34: =IFERROR(_xlfn.IFNA(INDEX(Sensors_MANU!$E$2:$E$4692,MATCH($D34,Sensors_MANU!$B$2:$B$4692,0)),INDEX(Sensors_MANU!$E$2:$E$4692,MATCH($P34,Sensors_MANU!$A$2:$A$4692,0))),"") | B34: =IFERROR(INDEX(Companies!$A$3:$A$101,MATCH(A34,Companies!$B$3:$B$101,0)),"") | D34: DFD94D3E05FE | E34: =LEFT(D34,2)&":"&MID(D34,3,2)&":"&MID(D34,5,2)&":"&MID(D34,7,2)&":"&MID(D34,9,2)&":"&RIGHT(D34,2) | H34: 3D5E71425EC34201 | I34: =IFERROR(_xlfn.IFNA(INDEX(Sensors_MANU!$C$2:$C$4692,MATCH($D34,Sensors_MANU!$B$2:$B$4692,0)),INDEX(Sensors_MANU!$C$2:$C$4692,MATCH($P34,Sensors_MANU!$A$2:$A$4692,0))),"") | J34: =IFERROR(_xlfn.IFNA(INDEX(Sensors_MANU!$D$2:$D$4692,MATCH($D34,Sensors_MANU!$B$2:$B$4692,0)),INDEX(Sensors_MANU!$D$2:$D$4692,MATCH($P34,Sensors_MANU!$A$2:$A$4692,0))),"")
A35: =IFERROR(_xlfn.IFNA(INDEX(Sensors_MANU!$E$2:$E$4692,MATCH($D35,Sensors_MANU!$B$2:$B$4692,0)),INDEX(Sensors_MANU!$E$2:$E$4692,MATCH($P35,Sensors_MANU!$A$2:$A$4692,0))),"") | B35: =IFERROR(INDEX(Companies!$A$3:$A$101,MATCH(A35,Companies!$B$3:$B$101,0)),"") | D35: FCF111E90F9E | E35: =LEFT(D35,2)&":"&MID(D35,3,2)&":"&MID(D35,5,2)&":"&MID(D35,7,2)&":"&MID(D35,9,2)&":"&RIGHT(D35,2) | H35: C3E9F96F25AFC2B5 | I35: =IFERROR(_xlfn.IFNA(INDEX(Sensors_MANU!$C$2:$C$4692,MATCH($D35,Sensors_MANU!$B$2:$B$4692,0)),INDEX(Sensors_MANU!$C$2:$C$4692,MATCH($P35,Sensors_MANU!$A$2:$A$4692,0))),"") | J35: =IFERROR(_xlfn.IFNA(INDEX(Sensors_MANU!$D$2:$D$4692,MATCH($D35,Sensors_MANU!$B$2:$B$4692,0)),INDEX(Sensors_MANU!$D$2:$D$4692,MATCH($P35,Sensors_MANU!$A$2:$A$4692,0))),"")
A36: =IFERROR(_xlfn.IFNA(INDEX(Sensors_MANU!$E$2:$E$4692,MATCH($D36,Sensors_MANU!$B$2:$B$4692,0)),INDEX(Sensors_MANU!$E$2:$E$4692,MATCH($P36,Sensors_MANU!$A$2:$A$4692,0))),"") | B36: =IFERROR(INDEX(Companies!$A$3:$A$101,MATCH(A36,Companies!$B$3:$B$101,0)),"") | C36: =IFERROR(_xlfn.IFNA(INDEX(Sensors_MANU!$F$2:$F$4692,MATCH($D36,Sensors_MANU!$B$2:$B$4692,0)),INDEX(Sensors_MANU!$F$2:$F$4692,MATCH($P36,Sensors_MANU!$A$2:$A$4692,0))),"") | D36: C1386E70D7FC | E36: =LEFT(D36,2)&":"&MID(D36,3,2)&":"&MID(D36,5,2)&":"&MID(D36,7,2)&":"&MID(D36,9,2)&":"&RIGHT(D36,2) | H36: F09BFC6E7CA2C207 | I36: =IFERROR(_xlfn.IFNA(INDEX(Sensors_MANU!$C$2:$C$4692,MATCH($D36,Sensors_MANU!$B$2:$B$4692,0)),INDEX(Sensors_MANU!$C$2:$C$4692,MATCH($P36,Sensors_MANU!$A$2:$A$4692,0))),"") | J36: =IFERROR(_xlfn.IFNA(INDEX(Sensors_MANU!$D$2:$D$4692,MATCH($D36,Sensors_MANU!$B$2:$B$4692,0)),INDEX(Sensors_MANU!$D$2:$D$4692,MATCH($P36,Sensors_MANU!$A$2:$A$4692,0))),"") | N36: =IFERROR(INDEX(Sensors_MANU!$G$2:$G$4692,MATCH($P36,Sensors_MANU!$A$2:$A$4692,0)),) | O36: v17 | P36: 4978649
A37: =IFERROR(_xlfn.IFNA(INDEX(Sensors_MANU!$E$2:$E$4692,MATCH($D37,Sensors_MANU!$B$2:$B$4692,0)),INDEX(Sensors_MANU!$E$2:$E$4692,MATCH($P37,Sensors_MANU!$A$2:$A$4692,0))),"") | B37: =IFERROR(INDEX(Companies!$A$3:$A$101,MATCH(A37,Companies!$B$3:$B$101,0)),"") | C37: cargo | D37: CFB783D03FEC | E37: =LEFT(D37,2)&":"&MID(D37,3,2)&":"&MID(D37,5,2)&":"&MID(D37,7,2)&":"&MID(D37,9,2)&":"&RIGHT(D37,2) | H37: 925CEB023538470D | I37: =IFERROR(_xlfn.IFNA(INDEX(Sensors_MANU!$C$2:$C$4692,MATCH($D37,Sensors_MANU!$B$2:$B$4692,0)),INDEX(Sensors_MANU!$C$2:$C$4692,MATCH($P37,Sensors_MANU!$A$2:$A$4692,0))),"") | J37: =IFERROR(_xlfn.IFNA(INDEX(Sensors_MANU!$D$2:$D$4692,MATCH($D37,Sensors_MANU!$B$2:$B$4692,0)),INDEX(Sensors_MANU!$D$2:$D$4692,MATCH($P37,Sensors_MANU!$A$2:$A$4692,0))),"") | N37: =IFERROR(INDEX(Sensors_MANU!$G$2:$G$4692,MATCH($P37,Sensors_MANU!$A$2:$A$4692,0)),) | O37: v17 | P37: 4978646
A38: =IFERROR(_xlfn.IFNA(INDEX(Sensors_MANU!$E$2:$E$4692,MATCH($D38,Sensors_MANU!$B$2:$B$4692,0)),INDEX(Sensors_MANU!$E$2:$E$4692,MATCH($P38,Sensors_MANU!$A$2:$A$4692,0))),"") | B38: =IFERROR(INDEX(Companies!$A$3:$A$101,MATCH(A38,Companies!$B$3:$B$101,0)),"") | C38: =IFERROR(_xlfn.IFNA(INDEX(Sensors_MANU!$F$2:$F$4692,MATCH($D38,Sensors_MANU!$B$2:$B$4692,0)),INDEX(Sensors_MANU!$F$2:$F$4692,MATCH($P38,Sensors_MANU!$A$2:$A$4692,0))),"") | D38: C6BCF35A4CE4 | E38: =LEFT(D38,2)&":"&MID(D38,3,2)&":"&MID(D38,5,2)&":"&MID(D38,7,2)&":"&MID(D38,9,2)&":"&RIGHT(D38,2) | H38: 751FC6BC785AC829 | I38: =IFERROR(_xlfn.IFNA(INDEX(Sensors_MANU!$C$2:$C$4692,MATCH($D38,Sensors_MANU!$B$2:$B$4692,0)),INDEX(Sensors_MANU!$C$2:$C$4692,MATCH($P38,Sensors_MANU!$A$2:$A$4692,0))),"") | J38: =IFERROR(_xlfn.IFNA(INDEX(Sensors_MANU!$D$2:$D$4692,MATCH($D38,Sensors_MANU!$B$2:$B$4692,0)),INDEX(Sensors_MANU!$D$2:$D$4692,MATCH($P38,Sensors_MANU!$A$2:$A$4692,0))),"") | N38: =IFERROR(INDEX(Sensors_MANU!$G$2:$G$4692,MATCH($P38,Sensors_MANU!$A$2:$A$4692,0)),) | O38: v17 | P38: 4978588
A39: =IFERROR(_xlfn.IFNA(INDEX(Sensors_MANU!$E$2:$E$4692,MATCH($D39,Sensors_MANU!$B$2:$B$4692,0)),INDEX(Sensors_MANU!$E$2:$E$4692,MATCH($P39,Sensors_MANU!$A$2:$A$4692,0))),"") | B39: =IFERROR(INDEX(Companies!$A$3:$A$101,MATCH(A39,Companies!$B$3:$B$101,0)),"") | C39: =IFERROR(_xlfn.IFNA(INDEX(Sensors_MANU!$F$2:$F$4692,MATCH($D39,Sensors_MANU!$B$2:$B$4692,0)),INDEX(Sensors_MANU!$F$2:$F$4692,MATCH($P39,Sensors_MANU!$A$2:$A$4692,0))),"") | D39: C4210A5C9D5F | E39: =LEFT(D39,2)&":"&MID(D39,3,2)&":"&MID(D39,5,2)&":"&MID(D39,7,2)&":"&MID(D39,9,2)&":"&RIGHT(D39,2) | H39: A60A3BEB1BA8A1D5 | I39: =IFERROR(_xlfn.IFNA(INDEX(Sensors_MANU!$C$2:$C$4692,MATCH($D39,Sensors_MANU!$B$2:$B$4692,0)),INDEX(Sensors_MANU!$C$2:$C$4692,MATCH($P39,Sensors_MANU!$A$2:$A$4692,0))),"") | J39: =IFERROR(_xlfn.IFNA(INDEX(Sensors_MANU!$D$2:$D$4692,MATCH($D39,Sensors_MANU!$B$2:$B$4692,0)),INDEX(Sensors_MANU!$D$2:$D$4692,MATCH($P39,Sensors_MANU!$A$2:$A$4692,0))),"") | N39: =IFERROR(INDEX(Sensors_MANU!$G$2:$G$4692,MATCH($P39,Sensors_MANU!$A$2:$A$4692,0)),) | O39: v17 | P39: 4978546
A40: =IFERROR(_xlfn.IFNA(INDEX(Sensors_MANU!$E$2:$E$4692,MATCH($D40,Sensors_MANU!$B$2:$B$4692,0)),INDEX(Sensors_MANU!$E$2:$E$4692,MATCH($P40,Sensors_MANU!$A$2:$A$4692,0))),"") | B40: =IFERROR(INDEX(Companies!$A$3:$A$101,MATCH(A40,Companies!$B$3:$B$101,0)),"") | C40: =IFERROR(_xlfn.IFNA(INDEX(Sensors_MANU!$F$2:$F$4692,MATCH($D40,Sensors_MANU!$B$2:$B$4692,0)),INDEX(Sensors_MANU!$F$2:$F$4692,MATCH($P40,Sensors_MANU!$A$2:$A$4692,0))),"") | D40: FF3EF624B31A | E40: =LEFT(D40,2)&":"&MID(D40,3,2)&":"&MID(D40,5,2)&":"&MID(D40,7,2)&":"&MID(D40,9,2)&":"&RIGHT(D40,2) | H40: 706A317F95A263AE | I40: =IFERROR(_xlfn.IFNA(INDEX(Sensors_MANU!$C$2:$C$4692,MATCH($D40,Sensors_MANU!$B$2:$B$4692,0)),INDEX(Sensors_MANU!$C$2:$C$4692,MATCH($P40,Sensors_MANU!$A$2:$A$4692,0))),"") | J40: =IFERROR(_xlfn.IFNA(INDEX(Sensors_MANU!$D$2:$D$4692,MATCH($D40,Sensors_MANU!$B$2:$B$4692,0)),INDEX(Sensors_MANU!$D$2:$D$4692,MATCH($P40,Sensors_MANU!$A$2:$A$4692,0))),"") | N40: =IFERROR(INDEX(Sensors_MANU!$G$2:$G$4692,MATCH($P40,Sensors_MANU!$A$2:$A$4692,0)),) | O40: v16 | P40: 4978592
...

Sheet Companies
A1: Company ID from Ubidots | B1: Company name | C1: Description | D1: Sensor count
A2: 0 | C2: Not assigned | D2: =COUNTIF(Sensors_DynamoDB!A:A,Companies!$B2)
A3: 6253a7e00d7237fac4873b5f | B3: VIEZO | C3: UAB Nanoenergija | D3: =COUNTIF(Sensors_DynamoDB!A:A,Companies!$B3)
A4: 624fc8f3330443aa9315c03f | B4: HVLE | C4: Havelländische Eisenbahn | D4: =COUNTIF(Sensors_DynamoDB!A:A,Companies!$B4)
A5: 6252e06ae4fead0698ecb1c2 | B5: VTG | D5: =COUNTIF(Sensors_DynamoDB!A:A,Companies!$B5)
A6: 6252e05ac4cdf0210339bc38 | B6: SGL | D6: =COUNTIF(Sensors_DynamoDB!A:A,Companies!$B6)
A7: 6253a699db3e775e431dc685 | B7: LTG | C7: Lithuanian Railways | D7: =COUNTIF(Sensors_DynamoDB!A:A,Companies!$B7)
A8: 62584ba3be96790af19bb545 | B8: PACIFIC | C8: Australia | D8: =COUNTIF(Sensors_DynamoDB!A:A,Companies!$B8)
A9: 62711ed01d64ac000b03f2bd | B9: HUPAC | D9: =COUNTIF(Sensors_DynamoDB!A:A,Companies!$B9)
A10: 6260f34542ddde196df5c8e3 | B10: MEDWAY | D10: =COUNTIF(Sensors_DynamoDB!A:A,Companies!$B10)
A11: 6260f6ceb34bab192344ea55 | B11: EIFFAGE | D11: =COUNTIF(Sensors_DynamoDB!A:A,Companies!$B11)
A12: 6261004b42ddde1a38b86668 | B12: GROUPCAT | D12: =COUNTIF(Sensors_DynamoDB!A:A,Companies!$B12)
A13: 6260fc6723fcfa10add59420 | B13: FERTAGUS | D13: =COUNTIF(Sensors_DynamoDB!A:A,Companies!$B13)
A14: 626abc0670a2920f54e5f7da | B14: FERROTRAMVIARIA | D14: =COUNTIF(Sensors_DynamoDB!A:A,Companies!$B14)
A15: 628cda051ecd6f96ea60b96f | B15: EUROWAGON | D15: =COUNTIF(Sensors_DynamoDB!A:A,Companies!$B15)
A16: 629787b13d4ed3000b44ba66 | B16: TRANSFESA | D16: =COUNTIF(Sensors_DynamoDB!A:A,Companies!$B16)
A17: 628238caccc8f309a5a763d2 | B17: GFR | D17: =COUNTIF(Sensors_DynamoDB!A:A,Companies!$B17)
A18: 62c6a03d34a1ec0471ec669b | B18: AXBENET | D18: =COUNTIF(Sensors_DynamoDB!A:A,Companies!$B18)
A19: 62c6a0563f80c801e6b67915 | B19: RAILTRANS | D19: =COUNTIF(Sensors_DynamoDB!A:A,Companies!$B19)
A20: 62c71c5915ba6418a9fef9df | B20: AMBROGIO | D20: =COUNTIF(Sensors_DynamoDB!A:A,Companies!$B20)
... A38: 65bca6234396a6000bc12292 | B38: SUJAN | D38: =COUNTIF(Sensors_DynamoDB!A:A,Companies!$B38)
A39: 6601886f1586791ef0b15498 | B39: MULTIMEDA

Sheet Gateways_MANU
A1: Company | B1: Gateway case nr | C1: Particle S. nr. | D1: Comments/Date Added:
A2: PACIFIC | B2: GW2203-033
A3: PACIFIC | B3: GW2203-028
A4: RENFE | B4: GW2203-009 | D4: 2023 01 25
A5: HUPAC | B5: GW2203-037
A6: HUPAC | B6: GW2203-006
A7: HUPAC | B7: GW2203-043
A8: HUPAC | B8: GW2203-024
A9: HUPAC | B9: GW2203-031
A10: HUPAC | B10: GW2203-017
A11: HUPAC | B11: GW2203-035
A12: HUPAC | B12: GW2203-019
A13: TRANSFESA | B13: GW2203-30
B14: 44658
A15: SBB CARGO | B15: was_GW2206-043 | C15: P025AB029Y2E58M
A16: HUPAC | C16: P025AB035NST2GY | D16: Warranty
A17: LTG | B17: GW2206-085 | C17: P025AB106ULSBJC
A18: HUPAC | B18: was_GW2206-083 | C18: P025AB034UJR8WT | D18: Warranty
A19: HUPAC | B19: was_GW2206-094 | C19: P025AB110C8YB5K | D19: Warranty
B20: GW2206-030 | C20: P025AB110JXF9EP
B21: GW2206-034 | C21: P025AB110GJELH7
B22: GW2206-087 | C22: P025AB029SPD9RG
B23: GW2206-088 | C23: P025AB110PTH5C4
A24: HUPAC | C24: P025AB110CYFGSN | D24: Warranty
B25: was_GW2206-090 | C25: P025AB110GBWFCL
B26: GW2206-040 | C26: P025AB1066LHUEK
B27: GW2206-041 | C27: P025AB110AJVHBY
A28: VTG | B28: GW2206-086 | C28: P025AB035S76F4P
A29: HUPAC | C29: P025AB106R9KDYH | D29: Warranty
A30: EUROWAGON | B30: GW2206-008 | C30: P025AB045JVWDPX | D30: 19/07/22
A31: SBB CARGO | B31: GW2206-019 | C31: P025AB110H6FVU3 | D31: 19/07/22
A32: HVLE | B32: GW2206-054 | C32: P025AB110TU2L9D | D32: 19/07/22
A33: SBB CARGO | B33: was_GW2203-036 | C33: P025AB1106FLXD2 | D33: 19/07/22 | E33: case nr changed
A34: AMBROGIO | B34: GW2206-039 | C34: P025AB029VMW27B | D34: 44827
A35: RAILIZE | B35: GW2206-080 | C35: P025AB110XL2YF6 | D35: 44831
A36: RAILIZE | B36: GW2206-061 | D36: 44831
A37: RAILIZE | B37: GW2203-015 | D37: 44831
A38: RAILIZE | B38: GW2203-003 | D38: 44831
A39: TRANSFESA | B39: GW2206-077 | D39: 5.10.2022
A40: TRANSFESA | B40: GW2203-047 | D40: 5.10.2022
...

Sheet Sensors_MANU
A1: Sensor S. no. | B1: mac_address | C1: HA S. No. | D1: Case S. No. | E1: Company | F1: Type | G1: Comment | I1: PCB ID | J1: DATE ADDED
A2: 4978561 | C2: 22 | D2: PR-2203-104 | E2: HVLE | F2: Cargo | I2: =_xlfn.NUMBERVALUE(A2)
A3: 4978887 | C3: 42 | D3: PR-2203-042 | E3: HVLE | F3: Cargo | I3: =_xlfn.NUMBERVALUE(A3)
A4: 4978676 | C4: 18 | D4: PR-2203-106 | E4: HVLE | F4: Cargo | I4: =_xlfn.NUMBERVALUE(A4)
A5: 4978517 | C5: 24 | D5: PR-2203-108 | E5: HVLE | F5: Cargo | I5: =_xlfn.NUMBERVALUE(A5)
A6: 4978881 | C6: 58 | D6: PR-2203-001 | E6: HVLE | F6: Cargo | I6: =_xlfn.NUMBERVALUE(A6)
A7: 4978718 | C7: 26 | D7: PR-2203-107 | E7: HVLE | F7: Cargo | I7: =_xlfn.NUMBERVALUE(A7)
A8: 4978550 | C8: 44 | D8: PR-2203-087 | E8: HVLE | F8: Cargo | I8: =_xlfn.NUMBERVALUE(A8)
A9: 4978696 | C9: 36 | D9: PR-2203-057 | E9: HVLE | F9: Cargo | I9: =_xlfn.NUMBERVALUE(A9)
A10: 4978680 | C10: 14 | D10: PR-2203-084 | E10: HVLE | F10: Cargo | I10: =_xlfn.NUMBERVALUE(A10)
A11: 4978756 | C11: 4 | D11: PR-2203-095 | E11: HVLE | F11: Cargo | I11: =_xlfn.NUMBERVALUE(A11)
A12: 4978683 | C12: 40 | D12: PR-2203-046 | E12: HVLE | F12: Cargo | I12: =_xlfn.NUMBERVALUE(A12)
A13: 4978557 | C13: 6 | D13: PR-2203-039 | E13: HVLE | F13: Cargo | I13: =_xlfn.NUMBERVALUE(A13)
... A21: 4978748 | C21: 30 | D21: PR-2203-085 | E21: HVLE | F21: Cargo | I21: =_xlfn.NUMBERVALUE(A21)
A22: 4978623 | C22: HA-2203-020 | D22: PR-2203-060 | E22: PACIFIC | F22: Cargo | I22: =_xlfn.NUMBERVALUE(A22)
A23: 4978824 | C23: 50 | D23: PR-2203-412 | E23: HVLE | F23: Cargo | I23: =_xlfn.NUMBERVALUE(A23)
A24: 4978724 | C24: 28 | D24: PR-2203-043 | E24: HVLE | F24: Cargo | I24: =_xlfn.NUMBERVALUE(A24)
A25: 4978620 | C25: 46 | D25: PR-2203-101 | E25: HVLE | F25: Cargo | I25: =_xlfn.NUMBERVALUE(A25)
A26: 4978685 | C26: 52 | D26: PR-2203-091 | E26: HVLE | F26: Cargo | I26: =_xlfn.NUMBERVALUE(A26)
A27: 4978715 | C27: 60 | D27: PR-2203-111 | E27: HVLE | F27: Cargo | I27: =_xlfn.NUMBERVALUE(A27)
A28: 4978751 | C28: 48 | D28: PR-2203-015 | E28: HVLE | F28: Cargo | I28: =_xlfn.NUMBERVALUE(A28)
A29: 4978693 | C29: 54 | D29: shit-1 | F29: Cargo | I29: =_xlfn.NUMBERVALUE(A29)
A30: 4978528 | C30: 62 | D30: PR-2203-105 | E30: HVLE | F30: Cargo | I30: =_xlfn.NUMBERVALUE(A30)
A31: 4978530 | C31: 84 | D31: PR-2203-073 | E31: HVLE | F31: Cargo | I31: =_xlfn.NUMBERVALUE(A31)
A32: 4978698 | C32: 82 | D32: PR-2203-048 | E32: HVLE | F32: Cargo | I32: =_xlfn.NUMBERVALUE(A32)
A33: 4978700 | C33: 114 | D33: PR-2203-052 | E33: HVLE | F33: Cargo | I33: =_xlfn.NUMBERVALUE(A33)
A34: 4978644 | C34: 78 | D34: PR-2203-100 | E34: HVLE | F34: Cargo | I34: =_xlfn.NUMBERVALUE(A34)
A35: 4978515 | C35: 96 | D35: shit-2 | F35: Cargo | I35: =_xlfn.NUMBERVALUE(A35)
A36: 4978638 | C36: 118 | D36: PR-2203-077 | E36: HVLE | F36: Cargo | I36: =_xlfn.NUMBERVALUE(A36)
A37: 4978618 | C37: 122 | D37: PR-2203-072 | E37: HVLE | F37: Cargo | I37: =_xlfn.NUMBERVALUE(A37)
A38: 4978625 | C38: 68 | D38: PR-2203-034 | E38: HVLE | F38: Cargo | I38: =_xlfn.NUMBERVALUE(A38)
A39: 4978627 | C39: HA-2203-422 | D39: PR-2203-140 | E39: GFR | F39: Cargo | I39: =_xlfn.NUMBERVALUE(A39)
A40: 4978513 | C40: 100 | D40: PR-2203-050 | E40: HVLE | F40: Cargo | I40: =_xlfn.NUMBERVALUE(A40)
A41: 4978681 | C41: 116 | D41: PR-2203-088 | E41: HVLE | F41: Cargo | I41: =_xlfn.NUMBERVALUE(A41)
A42: 4978704 | C42: 106 | D42: PR-2203-078 | E42: HVLE | F42: Cargo | I42: =_xlfn.NUMBERVALUE(A42)
A43: 4978563 | C43: 112 | D43: PR-2203-005 | E43: HVLE | F43: Cargo | I43: =_xlfn.NUMBERVALUE(A43)
A44: 4978553 | C44: 110 | D44: PR-2203-017 | E44: HVLE | F44: Cargo | I44: =_xlfn.NUMBERVALUE(A44)
A45: 4978554 | C45: 72 | D45: PR-2203-074 | E45: HVLE | F45: Cargo | I45: =_xlfn.NUMBERVALUE(A45)
A46: 4978640 | C46: 94 | D46: PR-2203-035 | E46: HVLE | F46: Cargo | I46: =_xlfn.NUMBERVALUE(A46)
A47: 4978449 | C47: 70 | D47: PR-2203-094 | E47: SGL | F47: Link | I47: =_xlfn.NUMBERVALUE(A47)
...

Sheet Settings
D1: speed_filter | G1: processing_intervals | L1: 2 | M1: BLE_intervals | P1: low_voltage | S1: accelerometer | Y1: log_filters | Z1: sensor_config | AA1: processing_mode | AB1: FW_URL | AC1: Settings string
A2: Setting code | B2: Setting | C2: Description | D2: lower speed | E2: higher speed | F2: deviation | G2: long Slot | H2: scan slot | I2: short period | J2: long period | K2: measure delay | L2: sensor second wake | M2: split | N2: time-out | O2: watchdog | P2: low limit, V | Q2: high limit, V | R2: test period, s | S2: ODR, Hz | T2: low g sense, g | U2: low g dur, s | V2: high g sense, g | W2: high g dur, s | X2: init (active / failed) | Y2: =30,sensors.process=1,sensors.comm=1 | Z2: {\"RAIL_ACCEL_REC_RANGE_G\":16} | AA2: 0(normal):1(test) | AB2: http://ec2-35-157-185-34.eu-central-1.compute.amazonaws.com:8090/sensor?2.1/0.22/ | AC2: JSON
A3: 1 | B3: Shipping | C3: Mode for shipping devices | D3: 15.000000 | E3: 25.000000 | F3: 10.000000 | G3: 40 | H3: 600 | I3: =3600*12 | J3: =3600*12 | K3: 10 | L3: =600*L$1 | M3: 1 | N3: 60 | O3: 300 | P3: 2.500000 | Q3: 3.000000 | R3: 3600 | S3: 0.000000 | T3: 1.500000 | U3: 0.200000 | V3: 2.000000 | W3: 0.200000 | X3: active | Y3: =30 | Z3: {\"RAIL_ACCEL_REC_RANGE_G\":16} | AA3: 0 | AC3: ="{""" & $D$1 & """:""" & $D3 & "," & $E3 & "," & $F3 & """,""" & $G$1 & """:""" & $G3 & "," & $H3 & "," & $I3 & "," & $J3 & "," & $K3 & "," & $L3 & """,""" & $M$1 & """:""" & $M3 & "," & $N3 & "," & $O3 & """,""" & $P$1 & """:""" & $P3 & "," & $Q3 & "," & $R3 & """,""" & $S$1 & """:""" & $S3 & "," & $T3 & "," & $U3 & "," & $V3 & "," & $W3 & "," & $X3 & """,""" & $AB$1 & """:""" & $AB3 & """,""" & $Y$1 & """:""" & $Y3 & """,""" & $Z$1 & """:""" & $Z3 & """,""" & $AA$1 & """:""" & $AA3 & """}"
A4: =A3+1 | B4: Slow-5-12h | C4: Slow mode for low power operation | D4: =D3 | E4: =E3 | F4: =F3 | G4: =G3 | H4: 150 | I4: =3600*5 | J4: =3600*12 | K4: =K3 | L4: =200*L$1 | M4: =M3 | N4: =N3 | O4: =O3 | P4: =P3 | Q4: =Q3 | R4: =R3 | S4: =S3 | T4: =T3 | ... X4: =X3 | Y4: =30 | Z4: {\"RAIL_ACCEL_REC_RANGE_G\":16} | AA4: 0 | AC4: ="{""" & $D$1 & """:""" & $D4 & "," & $E4 & "," & $F4 & """,""" & $G$1 & """:""" & $G4 & "," & $H4 & "," & $I4 & "," & $J4 & "," & $K4 & "," & $L4 & """,""" & $M$1 & """:""" & $M4 & "," & $N4 & "," & $O4 & """,""" & $P$1 & """:""" & $P4 & "," & $Q4 & "," & $R4 & """,""" & $S$1 & """:""" & $S4 & "," & $T4 & "," & $U4 & "," & $V4 & "," & $W4 & "," & $X4 & """,""" & $AB$1 & """:""" & $AB4 & """,""" & $Y$1 & """:""" & $Y4 & """,""" & $Z$1 & """:""" & $Z4 & """,""" & $AA$1 & """:""" & $AA4 & """}"
