Workbook

Sheet Gateways_DynamoDB
A1: operator_name | B1: operator_id | C1: id | D1: sn | E1: case_nr | F1: settings | G1: wagon_nr | H1: imei | I1: board_model | J1: battery_mah | K1: installation_date | L1: placement | M1: installed_by | N1: note | O1: setting_string
B2: =IFERROR(INDEX(Companies!$A$3:$A$101,MATCH(A2,Companies!$B$3:$B$101,0)),"") | C2: e00fce68d5f6b9fb3caee958 | E2: GW2203-006 | F2: Normal-2-6h | I2: T523M | J2: 19800 | O2: =IFERROR(INDEX(Settings!$AC$3:$AC$95,MATCH(Gateways_DynamoDB!$F2,Settings!$B$3:$B$95,0)),"")
B3: =IFERROR(INDEX(Companies!$A$3:$A$101,MATCH(A3,Companies!$B$3:$B$101,0)),"") | C3: e00fce68fe4dbdb9fab37607 | E3: GW2203-017 | F3: DD_ONLY_discovery | I3: T523M | J3: 19800 | N3: REFURBISHED | O3: =IFERROR(INDEX(Settings!$AC$3:$AC$95,MATCH(Gateways_DynamoDB!$F3,Settings!$B$3:$B$95,0)),"")
A4: TANKWAGON | B4: =IFERROR(INDEX(Companies!$A$3:$A$101,MATCH(A4,Companies!$B$3:$B$101,0)),"") | C4: e00fce6887c2f1e171208217 | E4: GW2203-019 | F4: Recovery-6-6h | G4: 33877916669-7 | I4: T523M | J4: 19800 | O4: =IFERROR(INDEX(Settings!$AC$3:$AC$95,MATCH(Gateways_DynamoDB!$F4,Settings!$B$3:$B$95,0)),"")
A5: =IFERROR(INDEX(Gateways_MANU!$A$2:$A$4949,MATCH($E5,Gateways_MANU!$B$2:$B$4949,0)),"") | B5: =IFERROR(INDEX(Companies!$A$3:$A$101,MATCH(A5,Companies!$B$3:$B$101,0)),"") | C5: e00fce688ca17b3f3592c148 | E5: GW2203-024 | F5: Normal-2-6h | G5: 33-85-4956-687-9 | I5: T523M | J5: 19800 | K5: 44832 | L5: L | M5: Hupac | N5: REFURBISHED | O5: =IFERROR(INDEX(Settings!$AC$3:$AC$95,MATCH(Gateways_DynamoDB!$F5,Settings!$B$3:$B$95,0)),"")
B6: =IFERROR(INDEX(Companies!$A$3:$A$101,MATCH(A6,Companies!$B$3:$B$101,0)),"") | C6: e00fce68c836b123fe66b5cc | E6: GW2203-031 | F6: DD_ONLY_discovery | I6: T523M | J6: 19800 | N6: REFURBISHED | O6: =IFERROR(INDEX(Settings!$AC$3:$AC$95,MATCH(Gateways_DynamoDB!$F6,Settings!$B$3:$B$95,0)),"")
B7: =IFERROR(INDEX(Companies!$A$3:$A$101,MATCH(A7,Companies!$B$3:$B$101,0)),"") | C7: e00fce68937b6b32fe0ec8c3 | E7: GW2203-035 | F7: DD_ONLY_discovery | I7: T523M | J7: 19800 | N7: REFURBISHED | O7: =IFERROR(INDEX(Settings!$AC$3:$AC$95,MATCH(Gateways_DynamoDB!$F7,Settings!$B$3:$B$95,0)),"")
A8: =IFERROR(INDEX(Gateways_MANU!$A$2:$A$4949,MATCH($E8,Gateways_MANU!$B$2:$B$4949,0)),"") | B8: =IFERROR(INDEX(Companies!$A$3:$A$101,MATCH(A8,Companies!$B$3:$B$101,0)),"") | C8: e00fce68f75fe3eac5ee7b0a | E8: GW2203-037 | F8: Normal-2-6h | G8: 33-85-4506-155-2 | I8: T523M | J8: 19800 | K8: 44832 | L8: L | M8: Hupac | N8: REFURBISHED | O8: =IFERROR(INDEX(Settings!$AC$3:$AC$95,MATCH(Gateways_DynamoDB!$F8,Settings!$B$3:$B$95,0)),"")
C9: e00fce6843cf275e71c9114a | E9: GW2203-043 | F9: Shipping | I9: T523M | J9: 19800 | N9: REFURBISHED | O9: =IFERROR(INDEX(Settings!$AC$3:$AC$95,MATCH(Gateways_DynamoDB!$F9,Settings!$B$3:$B$95,0)),"")
B10: =IFERROR(INDEX(Companies!$A$3:$A$101,MATCH(A10,Companies!$B$3:$B$101,0)),"") | C10: e00fce6896f7577f9882a05e | D10: P025AB035NST2GY | E10: GW2206-011 | F10: Slow-5-12h | I10: T523M | J10: =6600*3 | O10: =IFERROR(INDEX(Settings!$AC$3:$AC$95,MATCH(Gateways_DynamoDB!$F10,Settings!$B$3:$B$95,0)),"")
A11: TANKWAGON | B11: =IFERROR(INDEX(Companies!$A$3:$A$101,MATCH(A11,Companies!$B$3:$B$101,0)),"") | C11: e00fce68ad614837daa82ef5 | D11: P025AB110CYFGSN | E11: GW2206-060 | F11: Normal-2-6h | G11: 33747913061-5 | I11: T523M | J11: =6600*3 | O11: =IFERROR(INDEX(Settings!$AC$3:$AC$95,MATCH(Gateways_DynamoDB!$F11,Settings!$B$3:$B$95,0)),"")
A12: HUPAC | B12: =IFERROR(INDEX(Companies!$A$3:$A$101,MATCH(A12,Companies!$B$3:$B$101,0)),"") | C12: e00fce68fabaf7b85132d014 | D12: P025AB106R9KDYH | E12: GW2206-089 | F12: Normal-2-6h | G12: 33-85-4956-687-9 | I12: T523M | J12: =6600*3 | K12: 44832 | L12: R | M12: Hupac | N12: REFURBISHED | O12: =IFERROR(INDEX(Settings!$AC$3:$AC$95,MATCH(Gateways_DynamoDB!$F12,Settings!$B$3:$B$95,0)),"")
A13: VTG | B13: =IFERROR(INDEX(Companies!$A$3:$A$101,MATCH(A13,Companies!$B$3:$B$101,0)),"") | C13: e00fce68460536b41089cff8 | D13: P025AB029SKJB5U | E13: GW2203-041 | F13: Shipping | H13: 867648041711084 | I13: T523M | J13: 19800 | N13: The device is with VTG, would like to get it back. Not monitored on Ubidots anymore. | O13: =IFERROR(INDEX(Settings!$AC$3:$AC$95,MATCH(Gateways_DynamoDB!$F13,Settings!$B$3:$B$95,0)),"")
A14: VTG | B14: =IFERROR(INDEX(Companies!$A$3:$A$101,MATCH(A14,Companies!$B$3:$B$101,0)),"") | C14: e00fce6851355da59013f2c4 | E14: GW2206-086 | F14: Shipping | N14: The device is with VTG, would like to get it back. Not monitored on Ubidots anymore. | O14: =IFERROR(INDEX(Settings!$AC$3:$AC$95,MATCH(Gateways_DynamoDB!$F14,Settings!$B$3:$B$95,0)),"")
A15: TANKWAGON | B15: =IFERROR(INDEX(Companies!$A$3:$A$101,MATCH(A15,Companies!$B$3:$B$101,0)),"") | C15: e00fce68dcd8c78ed63ea671 | E15: GW2203-022 | F15: NO_SPEED_2h | G15: 33857929905-2 | I15: T523M | J15: =3*6600 | K15: 45210 | L15: L | M15: TANKWAGON | N15: REFURBISHED | O15: =IFERROR(INDEX(Settings!$AC$3:$AC$95,MATCH(Gateways_DynamoDB!$F15,Settings!$B$3:$B$95,0)),"")
A16: AMBROGIO | B16: =IFERROR(INDEX(Companies!$A$3:$A$101,MATCH(A16,Companies!$B$3:$B$101,0)),"") | C16: e00fce68afcedd2b5f45923c | D16: P025AB029VMW27B | E16: GW2206-039 | F16: Shipping | G16: 33-83-495-4-940-6 | I16: T523M | J16: =6600*3 | K16: 44832 | L16: L | M16: Viezo | O16: =IFERROR(INDEX(Settings!$AC$3:$AC$95,MATCH(Gateways_DynamoDB!$F16,Settings!$B$3:$B$95,0)),"")
A17: TRANSFESA | B17: =IFERROR(INDEX(Companies!$A$3:$A$101,MATCH(A17,Companies!$B$3:$B$101,0)),"") | C17: e00fce6819fe1dab0cbaa87e | D17: P025AB028DKE4WY | E17: GW2206-077 | F17: Recovery-6-6h | G17: 24714450036-7 | H17: 867648041714096 | I17: T523M | J17: 19800 | K17: 44893 | O17: =IFERROR(INDEX(Settings!$AC$3:$AC$95,MATCH(Gateways_DynamoDB!$F17,Settings!$B$3:$B$95,0)),"")
A18: TANKWAGON | B18: =IFERROR(INDEX(Companies!$A$3:$A$101,MATCH(A18,Companies!$B$3:$B$101,0)),"") | C18: e00fce68c2592b9188efd2c9 | D18: P025AB028C6AVWK | E18: GW2203-021 | F18: Normal-2-6h | G18: 33877916663-0 | H18: 867648041704329 | I18: T523M | J18: 19800 | N18: was_GW2206-080 | O18: =IFERROR(INDEX(Settings!$AC$3:$AC$95,MATCH(Gateways_DynamoDB!$F18,Settings!$B$3:$B$95,0)),"")
A19: TANKWAGON | B19: =IFERROR(INDEX(Companies!$A$3:$A$101,MATCH(A19,Companies!$B$3:$B$101,0)),"") | C19: e00fce68122c671cbe1f1ff1 | E19: GW2203-003 | F19: Fast-1-3h | G19: 33877916666-3 | O19: =IFERROR(INDEX(Settings!$AC$3:$AC$95,MATCH(Gateways_DynamoDB!$F19,Settings!$B$3:$B$95,0)),"")
B20: =IFERROR(INDEX(Companies!$A$3:$A$101,MATCH(A20,Companies!$B$3:$B$101,0)),"") | C20: e00fce683054951baa398b52 | E20: GW2203-015 | F20: Shipping | O20: =IFERROR(INDEX(Settings!$AC$3:$AC$95,MATCH(Gateways_DynamoDB!$F20,Settings!$B$3:$B$95,0)),"")
A21: RAILIZE | B21: =IFERROR(INDEX(Companies!$A$3:$A$101,MATCH(A21,Companies!$B$3:$B$101,0)),"") | C21: e00fce68fee664d352aabbb4 | D21: P025AB028UWJH3K | E21: GW2206-061 | F21: Shipping | H21: 867648041664994 | I21: T523M | J21: 19800 | O21: =IFERROR(INDEX(Settings!$AC$3:$AC$95,MATCH(Gateways_DynamoDB!$F21,Settings!$B$3:$B$95,0)),"")
A22: =IFERROR(INDEX(Gateways_MANU!$A$2:$A$4949,MATCH($E22,Gateways_MANU!$B$2:$B$4949,0)),"") | B22: =IFERROR(INDEX(Companies!$A$3:$A$101,MATCH(A22,Companies!$B$3:$B$101,0)),"") | C22: e00fce68f7915cebf1562e87 | E22: GW2203-007 | F22: Shipping | G22: 3354-3937-523-9 | J22: 19800 | K22: 44888 | M22: SGL | N22: The operator has the device or its lost (they paid for it), but we dont monitor it on Ubidots anymore. | O22: =IFERROR(INDEX(Settings!$AC$3:$AC$95,MATCH(Gateways_DynamoDB!$F22,Settings!$B$3:$B$95,0)),"")
A23: =IFERROR(INDEX(Gateways_MANU!$A$2:$A$4949,MATCH($E23,Gateways_MANU!$B$2:$B$4949,0)),"") | B23: =IFERROR(INDEX(Companies!$A$3:$A$101,MATCH(A23,Companies!$B$3:$B$101,0)),"") | C23: e00fce6831de67dd448473e9 | D23: P025AB0296GK27H | E23: GW2206-094 | F23: Recovery-6-6h | G23: 83546985088-6 | H23: 867648041698265 | J23: =3*6600 | K23: 44909 | L23: R | M23: HVLE | N23: 44876 | O23: =IFERROR(INDEX(Settings!$AC$3:$AC$95,MATCH(Gateways_DynamoDB!$F23,Settings!$B$3:$B$95,0)),"")
A24: CFLCARGO | B24: =IFERROR(INDEX(Companies!$A$3:$A$101,MATCH(A24,Companies!$B$3:$B$101,0)),"") | C24: e00fce6884e6fce92e4a8614 | D24: P025AB110468W3Y | E24: GW2206-093 | F24: NO_SPEED_2h | G24: MAK314 | I24: T523M | J24: =6600*3 | O24: =IFERROR(INDEX(Settings!$AC$3:$AC$95,MATCH(Gateways_DynamoDB!$F24,Settings!$B$3:$B$95,0)),"")
A25: =IFERROR(T(INDEX(Gateways_MANU!$A$2:$A$4949,MATCH($E25,Gateways_MANU!$B$2:$B$4949,0))),"") | B25: =IFERROR(INDEX(Companies!$A$3:$A$101,MATCH(A25,Companies!$B$3:$B$101,0)),"") | C25: e00fce68e97726618903cccc | D25: P025AB029EJ2594 | E25: GW2206-084 | F25: Slow-5-12h | G25: 33854668206-7 | I25: T523M | J25: =6600*3 | K25: 44918 | L25: L | M25: Viezo | O25: =IFERROR(INDEX(Settings!$AC$3:$AC$95,MATCH(Gateways_DynamoDB!$F25,Settings!$B$3:$B$95,0)),"")
A26: RENFE | B26: =IFERROR(INDEX(Companies!$A$3:$A$101,MATCH(A26,Companies!$B$3:$B$101,0)),"") | C26: e00fce6806eb219a43754b61 | D26: P025AB1109GN7DK | E26: GW2203-027 | F26: NO_SPEED_4h | G26: 527017 | I26: T523M | J26: =6600*3 | O26: =IFERROR(INDEX(Settings!$AC$3:$AC$95,MATCH(Gateways_DynamoDB!$F26,Settings!$B$3:$B$95,0)),"")
A27: TANKWAGON | B27: =IFERROR(INDEX(Companies!$A$3:$A$101,MATCH(A27,Companies!$B$3:$B$101,0)),"") | C27: e00fce68193d8bb1b06adc22 | D27: P025AB110H6FVU3 | E27: GW2206-019 | F27: Normal-2-6h | G27: 33877916681-2 | I27: T523M | J27: =6600*3 | O27: =IFERROR(INDEX(Settings!$AC$3:$AC$95,MATCH(Gateways_DynamoDB!$F27,Settings!$B$3:$B$95,0)),"")
A28: =IFERROR(INDEX(Gateways_MANU!$A$2:$A$4949,MATCH($E28,Gateways_MANU!$B$2:$B$4949,0)),"") | B28: =IFERROR(INDEX(Companies!$A$3:$A$101,MATCH(A28,Companies!$B$3:$B$101,0)),"") | C28: e00fce68fddc3f4dcf9a3b74 | E28: GW2203-034 | F28: Shipping | N28: The operator has the device or its lost (they paid for it), but we dont monitor it on Ubidots anymore. | O28: =IFERROR(INDEX(Settings!$AC$3:$AC$95,MATCH(Gateways_DynamoDB!$F28,Settings!$B$3:$B$95,0)),"")
A29: =IFERROR(INDEX(Gateways_MANU!$A$2:$A$4949,MATCH($E29,Gateways_MANU!$B$2:$B$4949,0)),"") | B29: =IFERROR(INDEX(Companies!$A$3:$A$101,MATCH(A29,Companies!$B$3:$B$101,0)),"") | C29: e00fce6853420f8642781437 | E29: GW2203-049 | F29: Shipping | N29: The operator has the device or its lost (they paid for it), but we dont monitor it on Ubidots anymore. | O29: =IFERROR(INDEX(Settings!$AC$3:$AC$95,MATCH(Gateways_DynamoDB!$F29,Settings!$B$3:$B$95,0)),"")
A30: =IFERROR(INDEX(Gateways_MANU!$A$2:$A$4949,MATCH($E30,Gateways_MANU!$B$2:$B$4949,0)),"") | B30: =IFERROR(INDEX(Companies!$A$3:$A$101,MATCH(A30,Companies!$B$3:$B$101,0)),"") | C30: e00fce68d32ab7e19cf847bf | F30: Normal-2-6h | G30: 84515332773-7 | K30: 44873 | L30: R | M30: Viezo | O30: =IFERROR(INDEX(Settings!$AC$3:$AC$95,MATCH(Gateways_DynamoDB!$F30,Settings!$B$3:$B$95,0)),"")
A31: CFLCARGO | B31: =IFERROR(INDEX(Companies!$A$3:$A$101,MATCH(A31,Companies!$B$3:$B$101,0)),"") | C31: e00fce686488370d15054e7b | D31: P025AB029H378CD | E31: GW2206-056 | F31: Recovery-6-6h | G31: MAK309 | N31: was GW2203-012 | O31: =IFERROR(INDEX(Settings!$AC$3:$AC$95,MATCH(Gateways_DynamoDB!$F31,Settings!$B$3:$B$95,0)),"")
A32: =IFERROR(INDEX(Gateways_MANU!$A$2:$A$4949,MATCH($E32,Gateways_MANU!$B$2:$B$4949,0)),"") | B32: =IFERROR(INDEX(Companies!$A$3:$A$101,MATCH(A32,Companies!$B$3:$B$101,0)),"") | C32: e00fce6813144c5e8a15791e | E32: GW2203-023 | F32: Slow-5-12h | G32: R3555 | K32: 44862 | M32: Fertagus | O32: =IFERROR(INDEX(Settings!$AC$3:$AC$95,MATCH(Gateways_DynamoDB!$F32,Settings!$B$3:$B$95,0)),"")
A33: FERTAGUS | B33: =IFERROR(INDEX(Companies!$A$3:$A$101,MATCH(A33,Companies!$B$3:$B$101,0)),"") | C33: e00fce68962f04b2507c174f | D33: P025AB0293NU7YX | E33: GW2203-020 | F33: Slow-5-12h | G33: M3555 | K33: 44862 | M33: Fertagus | O33: =IFERROR(INDEX(Settings!$AC$3:$AC$95,MATCH(Gateways_DynamoDB!$F33,Settings!$B$3:$B$95,0)),"")
A34: =IFERROR(T(INDEX(Gateways_MANU!$A$2:$A$4949,MATCH($E34,Gateways_MANU!$B$2:$B$4949,0))),"") | B34: =IFERROR(INDEX(Companies!$A$3:$A$101,MATCH(A34,Companies!$B$3:$B$101,0)),"") | C34: e00fce68435a9c417f84ebb9 | D34: P025AB110SCH4BF | E34: was_GW2206-091_ | F34: Shipping | I34: T523M | J34: =6600*3 | O34: =IFERROR(INDEX(Settings!$AC$3:$AC$95,MATCH(Gateways_DynamoDB!$F34,Settings!$B$3:$B$95,0)),"")
A35: =IFERROR(T(INDEX(Gateways_MANU!$A$2:$A$4949,MATCH($E35,Gateways_MANU!$B$2:$B$4949,0))),"") | B35: =IFERROR(INDEX(Companies!$A$3:$A$101,MATCH(A35,Companies!$B$3:$B$101,0)),"") | C35: e00fce682cc4e7703b017399 | D35: P025AB106B7TCKY | E35: GW2206-092 | F35: Fast-1-3h | G35: 31834589939-3 | I35: T523M | J35: =6600*3 | M35: Mercitalia | O35: =IFERROR(INDEX(Settings!$AC$3:$AC$95,MATCH(Gateways_DynamoDB!$F35,Settings!$B$3:$B$95,0)),"")
A36: =IFERROR(INDEX(Gateways_MANU!$A$2:$A$4949,MATCH($E36,Gateways_MANU!$B$2:$B$4949,0)),"") | B36: =IFERROR(INDEX(Companies!$A$3:$A$101,MATCH(A36,Companies!$B$3:$B$101,0)),"") | C36: e00fce68109636a0fd8cf124 | E36: GW2206-083 | F36: Recovery-6-6h | G36: 83546985085-2 | I36: T523M | J36: 19800 | K36: 44880 | L36: L | M36: Viezo | N36: 44876 | O36: =IFERROR(INDEX(Settings!$AC$3:$AC$95,MATCH(Gateways_DynamoDB!$F36,Settings!$B$3:$B$95,0)),"")
A37: =IFERROR(INDEX(Gateways_MANU!$A$2:$A$4949,MATCH($E37,Gateways_MANU!$B$2:$B$4949,0)),"") | B37: =IFERROR(INDEX(Companies!$A$3:$A$101,MATCH(A37,Companies!$B$3:$B$101,0)),"") | C37: e00fce68a175ae2bbe0a0169 | E37: GW2203-026 | F37: Recovery-6-6h | G37: 31833916501-7 | I37: T523M | J37: 19800 | M37: Mercitalia | O37: =IFERROR(INDEX(Settings!$AC$3:$AC$95,MATCH(Gateways_DynamoDB!$F37,Settings!$B$3:$B$95,0)),"")
A38: TRANSFESA | B38: =IFERROR(INDEX(Companies!$A$3:$A$101,MATCH(A38,Companies!$B$3:$B$101,0)),"") | C38: e00fce68d6e6b7a6e0da65b2 | E38: GW2203-047 | F38: Recovery-6-6h | G38: 43714378393-8 | I38: T523M | J38: 19800 | K38: 44893 | O38: =IFERROR(INDEX(Settings!$AC$3:$AC$95,MATCH(Gateways_DynamoDB!$F38,Settings!$B$3:$B$95,0)),"")
B39: =IFERROR(INDEX(Companies!$A$3:$A$101,MATCH(A39,Companies!$B$3:$B$101,0)),"") | C39: e00fce6854a172d6ecf1f509 | D39: P025AB0348L7M2T | E39: GW2205-TR01 | F39: Normal-2-6h | H39: 867648041668953 | I39: T523M | J39: 19800 | N39: warranty | O39: =IFERROR(INDEX(Settings!$AC$3:$AC$95,MATCH(Gateways_DynamoDB!$F39,Settings!$B$3:$B$95,0)),"")
B40: =IFERROR(INDEX(Companies!$A$3:$A$101,MATCH(A40,Companies!$B$3:$B$101,0)),"") | C40: e00fce689be64a638dd177f1 | D40: P025AB0347GFU25 | E40: GW2205-TR02 | F40: Normal-2-6h | I40: T523M | N40: warranty | O40: =IFERROR(INDEX(Settings!$AC$3:$AC$95,MATCH(Gateways_DynamoDB!$F40,Settings!$B$3:$B$95,0)),"")
...

Sheet Sensors_DynamoDB
A1: operator_name | B1: operator_id | C1: wagon_type | D1: mac_addr | E1: mac_addr_full | F1: installation_date | G1: installed_by | H1: sn | I1: harvester_id | J1: case_nr | K1: wagon_nr | L1: placement | M1: axle_nr | N1: note | O1: fw_version | P1: pcb_sn
A2: =IFERROR(_xlfn.IFNA(INDEX(Sensors_MANU!$E$2:$E$4692,MATCH($D2,Sensors_MANU!$B$2:$B$4692,0)),INDEX(Sensors_MANU!$E$2:$E$4692,MATCH($P2,Sensors_MANU!$A$2:$A$4692,0))),"") | B2: =IFERROR(INDEX(Companies!$A$3:$A$101,MATCH(A2,Companies!$B$3:$B$101,0)),"") | C2: Cargo | D2: EC5EDE1E5DAC | E2: =LEFT(D2,2)&":"&MID(D2,3,2)&":"&MID(D2,5,2)&":"&MID(D2,7,2)&":"&MID(D2,9,2)&":"&RIGHT(D2,2) | H2: 9BD0F696F03648E2 | I2: =IFERROR(_xlfn.IFNA(INDEX(Sensors_MANU!$C$2:$C$4692,MATCH($D2,Sensors_MANU!$B$2:$B$4692,0)),INDEX(Sensors_MANU!$C$2:$C$4692,MATCH($P2,Sensors_MANU!$A$2:$A$4692,0))),"") | J2: =IFERROR(_xlfn.IFNA(INDEX(Sensors_MANU!$D$2:$D$4692,MATCH($D2,Sensors_MANU!$B$2:$B$4692,0)),INDEX(Sensors_MANU!$D$2:$D$4692,MATCH($P2,Sensors_MANU!$A$2:$A$4692,0))),"") | N2: =IFERROR(INDEX(Sensors_MANU!$G$2:$G$4692,MATCH($P2,Sensors_MANU!$A$2:$A$4692,0)),) | O2: v15 | P2: 4978893
D3: FFD3024FF294 | H3: 1CB77F4BF34E379E | J3: VIEZO1CB77F4BF34E379E
D4: F0842AA2C9A4 | H4: 6771875AE0A36811 | J4: VIEZO6771875AE0A36811
D5: F81E2490F9EC | H5: 08BE71E6F7DB7373 | J5: VIEZO08BE71E6F7DB7373

Sheet Companies
A1: Company ID from Ubidots | B1: Company name | C1: Description | D1: Sensor count
A2: 0 | C2: Not assigned | D2: =COUNTIF(Sensors_DynamoDB!A:A,Companies!$B2)
A3: 6253a7e00d7237fac4873b5f | B3: VIEZO | C3: UAB Nanoenergija | D3: =COUNTIF(Sensors_DynamoDB!A:A,Companies!$B3)
A4: 624fc8f3330443aa9315c03f | B4: HVLE | C4: Havelländische Eisenbahn | D4: =COUNTIF(Sensors_DynamoDB!A:A,Companies!$B4)
A5: 6252e06ae4fead0698ecb1c2 | B5: VTG | D5: =COUNTIF(Sensors_DynamoDB!A:A,Companies!$B5)
A6: 6252e05ac4cdf0210339bc38 | B6: SGL | D6: =COUNTIF(Sensors_DynamoDB!A:A,Companies!$B6)
A7: 6253a699db3e775e431dc685 | B7: LTG | C7: Lithuanian Railways | D7: =COUNTIF(Sensors_DynamoDB!A:A,Companies!$B7)
A8: 62584ba3be96790af19bb545 | B8: PACIFIC | C8: Australia | D8: =COUNTIF(Sensors_DynamoDB!A:A,Companies!$B8)
A9: 62711ed01d64ac000b03f2bd | B9: HUPAC | D9: =COUNTIF(Sensors_DynamoDB!A:A,Companies!$B9)
A10: 6260f34542ddde196df5c8e3 | B10: MEDWAY | D10: =COUNTIF(Sensors_DynamoDB!A:A,Companies!$B10)
A11: 6260f6ceb34bab192344ea55 | B11: EIFFAGE | D11: =COUNTIF(Sensors_DynamoDB!A:A,Companies!$B11)
A12: 6261004b42ddde1a38b86668 | B12: GROUPCAT | D12: =COUNTIF(Sensors_DynamoDB!A:A,Companies!$B12)
A13: 6260fc6723fcfa10add59420 | B13: FERTAGUS | D13: =COUNTIF(Sensors_DynamoDB!A:A,Companies!$B13)
A14: 626abc0670a2920f54e5f7da | B14: FERROTRAMVIARIA | D14: =COUNTIF(Sensors_DynamoDB!A:A,Companies!$B14)
A15: 628cda051ecd6f96ea60b96f | B15: EUROWAGON | D15: =COUNTIF(Sensors_DynamoDB!A:A,Companies!$B15)
A16: 629787b13d4ed3000b44ba66 | B16: TRANSFESA | D16: =COUNTIF(Sensors_DynamoDB!A:A,Companies!$B16)
A17: 628238caccc8f309a5a763d2 | B17: GFR | D17: =COUNTIF(Sensors_DynamoDB!A:A,Companies!$B17)
A18: 62c6a03d34a1ec0471ec669b | B18: AXBENET | D18: =COUNTIF(Sensors_DynamoDB!A:A,Companies!$B18)
A19: 62c6a0563f80c801e6b67915 | B19: RAILTRANS | D19: =COUNTIF(Sensors_DynamoDB!A:A,Companies!$B19)
A20: 62c71c5915ba6418a9fef9df | B20: AMBROGIO | D20: =COUNTIF(Sensors_DynamoDB!A:A,Companies!$B20)
... A38: 65bca6234396a6000bc12292 | B38: SUJAN | D38: =COUNTIF(Sensors_DynamoDB!A:A,Companies!$B38)

Sheet Gateways_MANU
A1: Company | B1: Gateway case nr | C1: Particle S. nr. | D1: Comments/Date Added:
A2: PACIFIC | B2: GW2203-033
A3: PACIFIC | B3: GW2203-028
A4: RENFE | B4: GW2203-009 | D4: 2023 01 25
A5: HUPAC | B5: GW2203-037
A6: HUPAC | B6: GW2203-006
A7: HUPAC | B7: GW2203-043
A8: HUPAC | B8: GW2203-024
A9: HUPAC | B9: GW2203-031
A10: HUPAC | B10: GW2203-017
A11: HUPAC | B11: GW2203-035
A12: HUPAC | B12: GW2203-019
A13: TRANSFESA | B13: GW2203-30
B14: 44658
A15: SBB CARGO | B15: was_GW2206-043 | C15: P025AB029Y2E58M
A16: HUPAC | C16: P025AB035NST2GY | D16: Warranty
A17: LTG | B17: GW2206-085 | C17: P025AB106ULSBJC
A18: HUPAC | B18: was_GW2206-083 | C18: P025AB034UJR8WT | D18: Warranty
A19: HUPAC | B19: was_GW2206-094 | C19: P025AB110C8YB5K | D19: Warranty
B20: GW2206-030 | C20: P025AB110JXF9EP
B21: GW2206-034 | C21: P025AB110GJELH7
B22: GW2206-087 | C22: P025AB029SPD9RG
B23: GW2206-088 | C23: P025AB110PTH5C4
A24: HUPAC | C24: P025AB110CYFGSN | D24: Warranty
B25: was_GW2206-090 | C25: P025AB110GBWFCL
B26: GW2206-040 | C26: P025AB1066LHUEK
B27: GW2206-041 | C27: P025AB110AJVHBY
A28: VTG | B28: GW2206-086 | C28: P025AB035S76F4P
A29: HUPAC | C29: P025AB106R9KDYH | D29: Warranty
A30: EUROWAGON | B30: GW2206-008 | C30: P025AB045JVWDPX | D30: 19/07/22
A31: SBB CARGO | B31: GW2206-019 | C31: P025AB110H6FVU3 | D31: 19/07/22
A32: HVLE | B32: GW2206-054 | C32: P025AB110TU2L9D | D32: 19/07/22
A33: SBB CARGO | B33: was_GW2203-036 | C33: P025AB1106FLXD2 | D33: 19/07/22 | E33: case nr changed
A34: AMBROGIO | B34: GW2206-039 | C34: P025AB029VMW27B | D34: 44827
A35: RAILIZE | B35: GW2206-080 | C35: P025AB110XL2YF6 | D35: 44831
A36: RAILIZE | B36: GW2206-061 | D36: 44831
A37: RAILIZE | B37: GW2203-015 | D37: 44831
A38: RAILIZE | B38: GW2203-003 | D38: 44831
A39: TRANSFESA | B39: GW2206-077 | D39: 5.10.2022
A40: TRANSFESA | B40: GW2203-047 | D40: 5.10.2022
...

Sheet Sensors_MANU
A1: Sensor S. no. | B1: mac_address | C1: HA S. No. | D1: Case S. No. | E1: Company | F1: Type | G1: Comment | I1: PCB ID | J1: DATE ADDED
A2: 4978561 | C2: 22 | D2: PR-2203-104 | E2: HVLE | F2: Cargo | I2: =_xlfn.NUMBERVALUE(A2)
A3: 4978887 | C3: 42 | D3: PR-2203-042 | E3: HVLE | F3: Cargo | I3: =_xlfn.NUMBERVALUE(A3)
A4: 4978676 | C4: 18 | D4: PR-2203-106 | E4: HVLE | F4: Cargo | I4: =_xlfn.NUMBERVALUE(A4)
A5: 4978517 | C5: 24 | D5: PR-2203-108 | E5: HVLE | F5: Cargo | I5: =_xlfn.NUMBERVALUE(A5)
A6: 4978881 | C6: 58 | D6: PR-2203-001 | E6: HVLE | F6: Cargo | I6: =_xlfn.NUMBERVALUE(A6)
A7: 4978718 | C7: 26 | D7: PR-2203-107 | E7: HVLE | F7: Cargo | I7: =_xlfn.NUMBERVALUE(A7)
A8: 4978550 | C8: 44 | D8: PR-2203-087 | E8: HVLE | F8: Cargo | I8: =_xlfn.NUMBERVALUE(A8)
A9: 4978696 | C9: 36 | D9: PR-2203-057 | E9: HVLE | F9: Cargo | I9: =_xlfn.NUMBERVALUE(A9)
A10: 4978680 | C10: 14 | D10: PR-2203-084 | E10: HVLE | F10: Cargo | I10: =_xlfn.NUMBERVALUE(A10)
A11: 4978756 | C11: 4 | D11: PR-2203-095 | E11: HVLE | F11: Cargo | I11: =_xlfn.NUMBERVALUE(A11)
A12: 4978683 | C12: 40 | D12: PR-2203-046 | E12: HVLE | F12: Cargo | I12: =_xlfn.NUMBERVALUE(A12)
A13: 4978557 | C13: 6 | D13: PR-2203-039 | E13: HVLE | F13: Cargo | I13: =_xlfn.NUMBERVALUE(A13)
... A21: 4978748 | C21: 30 | D21: PR-2203-085 | E21: HVLE | F21: Cargo | I21: =_xlfn.NUMBERVALUE(A21)
A22: 4978623 | C22: HA-2203-020 | D22: PR-2203-060 | E22: PACIFIC | F22: Cargo | I22: =_xlfn.NUMBERVALUE(A22)
A23: 4978824 | C23: 50 | D23: PR-2203-412 | E23: HVLE | F23: Cargo | I23: =_xlfn.NUMBERVALUE(A23)
A24: 4978724 | C24: 28 | D24: PR-2203-043 | E24: HVLE | F24: Cargo | I24: =_xlfn.NUMBERVALUE(A24)
A25: 4978620 | C25: 46 | D25: PR-2203-101 | E25: HVLE | F25: Cargo | I25: =_xlfn.NUMBERVALUE(A25)
A26: 4978685 | C26: 52 | D26: PR-2203-091 | E26: HVLE | F26: Cargo | I26: =_xlfn.NUMBERVALUE(A26)
A27: 4978715 | C27: 60 | D27: PR-2203-111 | E27: HVLE | F27: Cargo | I27: =_xlfn.NUMBERVALUE(A27)
A28: 4978751 | C28: 48 | D28: PR-2203-015 | E28: HVLE | F28: Cargo | I28: =_xlfn.NUMBERVALUE(A28)
A29: 4978693 | C29: 54 | D29: shit-1 | F29: Cargo | I29: =_xlfn.NUMBERVALUE(A29)
A30: 4978528 | C30: 62 | D30: PR-2203-105 | E30: HVLE | F30: Cargo | I30: =_xlfn.NUMBERVALUE(A30)
A31: 4978530 | C31: 84 | D31: PR-2203-073 | E31: HVLE | F31: Cargo | I31: =_xlfn.NUMBERVALUE(A31)
A32: 4978698 | C32: 82 | D32: PR-2203-048 | E32: HVLE | F32: Cargo | I32: =_xlfn.NUMBERVALUE(A32)
A33: 4978700 | C33: 114 | D33: PR-2203-052 | E33: HVLE | F33: Cargo | I33: =_xlfn.NUMBERVALUE(A33)
A34: 4978644 | C34: 78 | D34: PR-2203-100 | E34: HVLE | F34: Cargo | I34: =_xlfn.NUMBERVALUE(A34)
A35: 4978515 | C35: 96 | D35: shit-2 | F35: Cargo | I35: =_xlfn.NUMBERVALUE(A35)
A36: 4978638 | C36: 118 | D36: PR-2203-077 | E36: HVLE | F36: Cargo | I36: =_xlfn.NUMBERVALUE(A36)
A37: 4978618 | C37: 122 | D37: PR-2203-072 | E37: HVLE | F37: Cargo | I37: =_xlfn.NUMBERVALUE(A37)
A38: 4978625 | C38: 68 | D38: PR-2203-034 | E38: HVLE | F38: Cargo | I38: =_xlfn.NUMBERVALUE(A38)
A39: 4978627 | C39: HA-2203-422 | D39: PR-2203-140 | E39: GFR | F39: Cargo | I39: =_xlfn.NUMBERVALUE(A39)
A40: 4978513 | C40: 100 | D40: PR-2203-050 | E40: HVLE | F40: Cargo | I40: =_xlfn.NUMBERVALUE(A40)
A41: 4978681 | C41: 116 | D41: PR-2203-088 | E41: HVLE | F41: Cargo | I41: =_xlfn.NUMBERVALUE(A41)
A42: 4978704 | C42: 106 | D42: PR-2203-078 | E42: HVLE | F42: Cargo | I42: =_xlfn.NUMBERVALUE(A42)
A43: 4978563 | C43: 112 | D43: PR-2203-005 | E43: HVLE | F43: Cargo | I43: =_xlfn.NUMBERVALUE(A43)
A44: 4978553 | C44: 110 | D44: PR-2203-017 | E44: HVLE | F44: Cargo | I44: =_xlfn.NUMBERVALUE(A44)
A45: 4978554 | C45: 72 | D45: PR-2203-074 | E45: HVLE | F45: Cargo | I45: =_xlfn.NUMBERVALUE(A45)
A46: 4978640 | C46: 94 | D46: PR-2203-035 | E46: HVLE | F46: Cargo | I46: =_xlfn.NUMBERVALUE(A46)
A47: 4978449 | C47: 70 | D47: PR-2203-094 | E47: SGL | F47: Link | I47: =_xlfn.NUMBERVALUE(A47)
...

Sheet Settings
D1: speed_filter | G1: processing_intervals | L1: 2 | M1: BLE_intervals | P1: low_voltage | S1: accelerometer | Y1: log_filters | Z1: sensor_config | AA1: processing_mode | AB1: FW_URL | AC1: Settings string
A2: Setting code | B2: Setting | C2: Description | D2: lower speed | E2: higher speed | F2: deviation | G2: long Slot | H2: scan slot | I2: short period | J2: long period | K2: measure delay | L2: sensor second wake | M2: split | N2: time-out | O2: watchdog | P2: low limit, V | Q2: high limit, V | R2: test period, s | S2: ODR, Hz | T2: low g sense, g | U2: low g dur, s | V2: high g sense, g | W2: high g dur, s | X2: init (active / failed) | Y2: =30,sensors.process=1,sensors.comm=1 | Z2: {\"RAIL_ACCEL_REC_RANGE_G\":16} | AA2: 0(normal):1(test) | AB2: http://ec2-35-157-185-34.eu-central-1.compute.amazonaws.com:8090/sensor?2.1/0.22/ | AC2: JSON
A3: 1 | B3: Shipping | C3: Mode for shipping devices | D3: 15.000000 | E3: 25.000000 | F3: 10.000000 | G3: 40 | H3: 600 | I3: =3600*12 | J3: =3600*12 | K3: 10 | L3: =600*L$1 | M3: 1 | N3: 60 | O3: 300 | P3: 2.500000 | Q3: 3.000000 | R3: 3600 | S3: 0.000000 | T3: 1.500000 | U3: 0.200000 | V3: 2.000000 | W3: 0.200000 | X3: active | Y3: =30 | Z3: {\"RAIL_ACCEL_REC_RANGE_G\":16} | AA3: 0 | AC3: ="{""" & $D$1 & """:""" & $D3 & "," & $E3 & "," & $F3 & """,""" & $G$1 & """:""" & $G3 & "," & $H3 & "," & $I3 & "," & $J3 & "," & $K3 & "," & $L3 & """,""" & $M$1 & """:""" & $M3 & "," & $N3 & "," & $O3 & """,""" & $P$1 & """:""" & $P3 & "," & $Q3 & "," & $R3 & """,""" & $S$1 & """:""" & $S3 & "," & $T3 & "," & $U3 & "," & $V3 & "," & $W3 & "," & $X3 & """,""" & $AB$1 & """:""" & $AB3 & """,""" & $Y$1 & """:""" & $Y3 & """,""" & $Z$1 & """:""" & $Z3 & """,""" & $AA$1 & """:""" & $AA3 & """}"
A4: =A3+1 | B4: Slow-5-12h | C4: Slow mode for low power operation | D4: =D3 | E4: =E3 | F4: =F3 | G4: =G3 | H4: 150 | I4: =3600*5 | J4: =3600*12 | K4: =K3 | L4: =200*L$1 | M4: =M3 | N4: =N3 | O4: =O3 | P4: =P3 | Q4: =Q3 | R4: =R3 | S4: =S3 | T4: =T3 | ... X4: =X3 | Y4: =30 | Z4: {\"RAIL_ACCEL_REC_RANGE_G\":16} | AA4: 0 | AC4: ="{""" & $D$1 & """:""" & $D4 & "," & $E4 & "," & $F4 & """,""" & $G$1 & """:""" & $G4 & "," & $H4 & "," & $I4 & "," & $J4 & "," & $K4 & "," & $L4 & """,""" & $M$1 & """:""" & $M4 & "," & $N4 & "," & $O4 & """,""" & $P$1 & """:""" & $P4 & "," & $Q4 & "," & $R4 & """,""" & $S$1 & """:""" & $S4 & "," & $T4 & "," & $U4 & "," & $V4 & "," & $W4 & "," & $X4 & """,""" & $AB$1 & """:""" & $AB4 & """,""" & $Y$1 & """:""" & $Y4 & """,""" & $Z$1 & """:""" & $Z4 & """,""" & $AA$1 & """:""" & $AA4 & """}"
A5: =A4+1 | B5: Normal-4-12h | C5: Normal operation mode | D5: =D4 | E5: =E4 | F5: =F4 | G5: =G4 | H5: 150 | I5: =3600*4 | J5: =3600*12 | K5: =K4 | L5: =60*L$1 | M5: =M4 | N5: =N4 | O5: =O4 | P5: =P4 | Q5: =Q4 | R5: =R4 | S5: =S4 | T5: =T4 | ... X5: =X4 | Y5: =30 | Z5: {\"RAIL_ACCEL_REC_RANGE_G\":16} | AA5: 0 | AC5: ="{""" & $D$1 & """:""" & $D5 & "," & $E5 & "," & $F5 & """,""" & $G$1 & """:""" & $G5 & "," & $H5 & "," & $I5 & "," & $J5 & "," & $K5 & "," & $L5 & """,""" & $M$1 & """:""" & $M5 & "," & $N5 & "," & $O5 & """,""" & $P$1 & """:""" & $P5 & "," & $Q5 & "," & $R5 & """,""" & $S$1 & """:""" & $S5 & "," & $T5 & "," & $U5 & "," & $V5 & "," & $W5 & "," & $X5 & """,""" & $AB$1 & """:""" & $AB5 & """,""" & $Y$1 & """:""" & $Y5 & """,""" & $Z$1 & """:""" & $Z5 & """,""" & $AA$1 & """:""" & $AA5 & """}"
A6: =A5+1 | B6: Fast-1-3h | C6: Fast mode for faster data collection | D6: =D5 | E6: =E5 | F6: =F5 | G6: =G5 | H6: 150 | I6: =3600*1 | J6: =3*3600 | K6: =K5 | L6: =60*L$1 | M6: =M5 | N6: =N5 | O6: =O5 | P6: =P5 | Q6: =Q5 | R6: =R5 | S6: =S5 | T6: =T5 | ... X6: =X5 | Y6: =30 | Z6: {\"RAIL_ACCEL_REC_RANGE_G\":16} | AA6: 0 | AC6: ="{""" & $D$1 & """:""" & $D6 & "," & $E6 & "," & $F6 & """,""" & $G$1 & """:""" & $G6 & "," & $H6 & "," & $I6 & "," & $J6 & "," & $K6 & "," & $L6 & """,""" & $M$1 & """:""" & $M6 & "," & $N6 & "," & $O6 & """,""" & $P$1 & """:""" & $P6 & "," & $Q6 & "," & $R6 & """,""" & $S$1 & """:""" & $S6 & "," & $T6 & "," & $U6 & "," & $V6 & "," & $W6 & "," & $X6 & """,""" & $AB$1 & """:""" & $AB6 & """,""" & $Y$1 & """:""" & $Y6 & """,""" & $Z$1 & """:""" & $Z6 & """,""" & $AA$1 & """:""" & $AA6 & """}"
A7: =A6+1 | B7: Super Fast-20min-1h | C7: High energy consumption mode | D7: =D6 | E7: =E6 | F7: =F6 | G7: =G6 | H7: 150 | I7: 1200 | J7: 3600 | K7: =K6 | L7: =200*L$1 | M7: =M6 | N7: =N6 | O7: =O6 | P7: =P6 | Q7: =Q6 | R7: =R6 | S7: =S6 | T7: =T6 | ... X7: =X6 | Y7: =30 | Z7: {\"RAIL_ACCEL_REC_RANGE_G\":16} | AA7: 0 | AC7: ="{""" & $D$1 & """:""" & $D7 & "," & $E7 & "," & $F7 & """,""" & $G$1 & """:""" & $G7 & "," & $H7 & "," & $I7 & "," & $J7 & "," & $K7 & "," & $L7 & """,""" & $M$1 & """:""" & $M7 & "," & $N7 & "," & $O7 & """,""" & $P$1 & """:""" & $P7 & "," & $Q7 & "," & $R7 & """,""" & $S$1 & """:""" & $S7 & "," & $T7 & "," & $U7 & "," & $V7 & "," & $W7 & "," & $X7 & """,""" & $AB$1 & """:""" & $AB7 & """,""" & $Y$1 & """:""" & $Y7 & """,""" & $Z$1 & """:""" & $Z7 & """,""" & $AA$1 & """:""" & $AA7 & """}"
A8: =A7+1 | B8: Assembly-20-20min | C8: For assembling sensors | D8: 0.001000 | E8: 0.001000 | F8: =F7 | G8: =G7 | H8: 800 | I8: 1200 | J8: 1200 | K8: =K7 | L8: =600*L$1 | M8: =M7 | N8: =N7 | O8: =O7 | P8: =P7 | Q8: =Q7 | R8: =R7 | S8: 0.000000 | T8: 1.500000 | U8: 0.200000 | V8: 2.000000 | W8: 0.200000 | X8: active | Y8: =30 | Z8: {\"RAIL_ACCEL_REC_RANGE_G\":16} | AA8: 0 | AC8: ="{""" & $D$1 & """:""" & $D8 & "," & $E8 & "," & $F8 & """,""" & $G$1 & """:""" & $G8 & "," & $H8 & "," & $I8 & "," & $J8 & "," & $K8 & "," & $L8 & """,""" & $M$1 & """:""" & $M8 & "," & $N8 & "," & $O8 & """,""" & $P$1 & """:""" & $P8 & "," & $Q8 & "," & $R8 & """,""" & $S$1 & """:""" & $S8 & "," & $T8 & "," & $U8 & "," & $V8 & "," & $W8 & "," & $X8 & """,""" & $AB$1 & """:""" & $AB8 & """,""" & $Y$1 & """:""" & $Y8 & """,""" & $Z$1 & """:""" & $Z8 & """,""" & $AA$1 & """:""" & $AA8 & """}"
A9: =A8+1 | B9: New FW Test | C9: For LTG tests | D9: 0.001000 | E9: 0.001000 | F9: =F8 | G9: =G8 | H9: 600 | I9: 1200 | J9: 3600 | K9: =K8 | L9: =200*L$1 | M9: =M8 | N9: =N8 | O9: =O8 | P9: =P8 | Q9: =Q8 | R9: =R8 | S9: =S8 | T9: =T8 | ... X9: =X8 | Y9: =30,sensors.process=1,sensors.comm=1 | Z9: {\"RAIL_ACCEL_REC_RANGE_G\":16} | AA9: 0 | AB9: http://ec2-35-157-185-34.eu-central-1.compute.amazonaws.com:8090/sensor?2.1/2.5/ | AC9: ="{""" & $D$1 & """:""" & $D9 & "," & $E9 & "," & $F9 & """,""" & $G$1 & """:""" & $G9 & "," & $H9 & "," & $I9 & "," & $J9 & "," & $K9 & "," & $L9 & """,""" & $M$1 & """:""" & $M9 & "," & $N9 & "," & $O9 & """,""" & $P$1 & """:""" & $P9 & "," & $Q9 & "," & $R9 & """,""" & $S$1 & """:""" & $S9 & "," & $T9 & "," & $U9 & "," & $V9 & "," & $W9 & "," & $X9 & """,""" & $AB$1 & """:""" & $AB9 & """,""" & $Y$1 & """:""" & $Y9 & """,""" & $Z$1 & """:""" & $Z9 & """,""" & $AA$1 & """:""" & $AA9 & """}"
A10: =A9+1 | B10: TEST_F1-30min-4h | C10: Testing parameters 1 | D10: 0.000000 | E10: 0.000000 | F10: =F9 | G10: =G9 | H10: 150 | I10: 1800 | J10: =3600*4 | K10: 10 | L10: =200*L$1 | M10: =M9 | N10: =N9 | O10: =O9 | P10: =P9 | Q10: =Q9 | R10: =R9 | S10: =S9 | T10: =T9 | ... X10: =X9 | Y10: =30,sensors.process=1,sensors.comm=1 | Z10: {\"RAIL_ACCEL_REC_RANGE_G\":16} | AA10: 0 | AB10: http://ec2-35-157-185-34.eu-central-1.compute.amazonaws.com:8090/sensor?2.1/0.24/ | AC10: ="{""" & $D$1 & """:""" & $D10 & "," & $E10 & "," & $F10 & """,""" & $G$1 & """:""" & $G10 & "," & $H10 & "," & $I10 & "," & $J10 & "," & $K10 & "," & $L10 & """,""" & $M$1 & """:""" & $M10 & "," & $N10 & "," & $O10 & """,""" & $P$1 & """:""" & $P10 & "," & $Q10 & "," & $R10 & """,""" & $S$1 & """:""" & $S10 & "," & $T10 & "," & $U10 & "," & $V10 & "," & $W10 & "," & $X10 & """,""" & $AB$1 & """:""" & $AB10 & """,""" & $Y$1 & """:""" & $Y10 & """,""" & $Z$1 & """:""" & $Z10 & """,""" & $AA$1 & """:""" & $AA10 & """}"
A11: =A10+1 | B11: Recovery-6-6h | C11: Mode for GW recovery | D11: 30.000000 | E11: 40.000000 | F11: =F10 | G11: =G10 | H11: 10 | I11: =3600*6 | J11: =3600*6 | K11: 10 | L11: =300*L$1 | M11: =M10 | N11: =N10 | O11: =O10 | P11: =P10 | Q11: =Q10 | R11: =R10 | S11: =S10 | T11: =T10 | ... X11: =X10 | Y11: =30 | Z11: {\"RAIL_ACCEL_REC_RANGE_G\":16} | AA11: 0 | AC11: ="{""" & $D$1 & """:""" & $D11 & "," & $E11 & "," & $F11 & """,""" & $G$1 & """:""" & $G11 & "," & $H11 & "," & $I11 & "," & $J11 & "," & $K11 & "," & $L11 & """,""" & $M$1 & """:""" & $M11 & "," & $N11 & "," & $O11 & """,""" & $P$1 & """:""" & $P11 & "," & $Q11 & "," & $R11 & """,""" & $S$1 & """:""" & $S11 & "," & $T11 & "," & $U11 & "," & $V11 & "," & $W11 & "," & $X11 & """,""" & $AB$1 & """:""" & $AB11 & """,""" & $Y$1 & """:""" & $Y11 & """,""" & $Z$1 & """:""" & $Z11 & """,""" & $AA$1 & """:""" & $AA11 & """}"
A12: =A11+1 | B12: Discovery | C12: Find all desynchronized sensors | D12: 15.000000 | E12: 25.000000 | F12: =F11 | G12: =G11 | H12: 600 | I12: 1200 | J12: =3600*2 | K12: 10 | L12: =300*L$1 | M12: 1 | N12: 60 | O12: 300 | P12: 2.500000 | Q12: 3.000000 | R12: 3600 | S12: 0.000000 | T12: 1.500000 | U12: 0.200000 | V12: 2.000000 | W12: 0.200000 | X12: active | Y12: =30 | Z12: {\"RAIL_ACCEL_REC_RANGE_G\":16} | AA12: 0 | AC12: ="{""" & $D$1 & """:""" & $D12 & "," & $E12 & "," & $F12 & """,""" & $G$1 & """:""" & $G12 & "," & $H12 & "," & $I12 & "," & $J12 & "," & $K12 & "," & $L12 & """,""" & $M$1 & """:""" & $M12 & "," & $N12 & "," & $O12 & """,""" & $P$1 & """:""" & $P12 & "," & $Q12 & "," & $R12 & """,""" & $S$1 & """:""" & $S12 & "," & $T12 & "," & $U12 & "," & $V12 & "," & $W12 & "," & $X12 & """,""" & $AB$1 & """:""" & $AB12 & """,""" & $Y$1 & """:""" & $Y12 & """,""" & $Z$1 & """:""" & $Z12 & """,""" & $AA$1 & """:""" & $AA12 & """}"
A13: =A12+1 | B13: TEST_F2-30min-1h | C13: Testing parameters 2 | D13: 0.000000 | E13: 0.000000 | F13: =F10 | G13: =G12 | H13: 600 | I13: 1800 | J13: =3600 | K13: 10 | L13: =200*L$1 | M13: =M11 | N13: =N11 | O13: =O11 | P13: =P11 | Q13: =Q11 | R13: =R11 | S13: =S11 | T13: =T11 | ... X13: =X11 | Y13: =30,sensors.process=1,sensors.comm=1 | Z13: {\"RAIL_ACCEL_REC_RANGE_G\":16} | AA13: 0 | AB13: http://ec2-35-157-185-34.eu-central-1.compute.amazonaws.com:8090/sensor?2.1/0.26/ | AC13: ="{""" & $D$1 & """:""" & $D13 & "," & $E13 & "," & $F13 & """,""" & $G$1 & """:""" & $G13 & "," & $H13 & "," & $I13 & "," & $J13 & "," & $K13 & "," & $L13 & """,""" & $M$1 & """:""" & $M13 & "," & $N13 & "," & $O13 & """,""" & $P$1 & """:""" & $P13 & "," & $Q13 & "," & $R13 & """,""" & $S$1 & """:""" & $S13 & "," & $T13 & "," & $U13 & "," & $V13 & "," & $W13 & "," & $X13 & """,""" & $AB$1 & """:""" & $AB13 & """,""" & $Y$1 & """:""" & $Y13 & """,""" & $Z$1 & """:""" & $Z13 & """,""" & $AA$1 & """:""" & $AA13 & """}"
A14: =A13+1 | B14: Normal-2-6h | C14: Normal mode with 2h+6h interval | D14: =D5 | E14: =E5 | F14: =F5 | G14: =G13 | H14: 150 | I14: =3600*2 | J14: =3600*6 | K14: =K5 | L14: =L5*L$1 | M14: =M5 | N14: =N5 | O14: =O5 | P14: =P5 | Q14: =Q5 | R14: =R5 | S14: =S5 | T14: =T5 | ... X14: =X5 | Y14: =30 | Z14: {\"RAIL_ACCEL_REC_RANGE_G\":16} | AA14: 0 | AC14: ="{""" & $D$1 & """:""" & $D14 & "," & $E14 & "," & $F14 & """,""" & $G$1 & """:""" & $G14 & "," & $H14 & "," & $I14 & "," & $J14 & "," & $K14 & "," & $L14 & """,""" & $M$1 & """:""" & $M14 & "," & $N14 & "," & $O14 & """,""" & $P$1 & """:""" & $P14 & "," & $Q14 & "," & $R14 & """,""" & $S$1 & """:""" & $S14 & "," & $T14 & "," & $U14 & "," & $V14 & "," & $W14 & "," & $X14 & """,""" & $AB$1 & """:""" & $AB14 & """,""" & $Y$1 & """:""" & $Y14 & """,""" & $Z$1 & """:""" & $Z14 & """,""" & $AA$1 & """:""" & $AA14 & """}"
A15: =A14+1 | B15: Certification | C15: Mode for certification bodies | D15: 15.000000 | E15: 25.000000 | F15: 10.000000 | G15: =G14 | H15: 300 | I15: 14400 | J15: 43200 | K15: 10 | L15: =200*L$1 | M15: 1 | N15: 60 | O15: 300 | P15: 2.500000 | Q15: 3.000000 | R15: 3600 | S15: 0.000000 | T15: 1.500000 | U15: 0.200000 | V15: 2.000000 | W15: 0.200000 | X15: active | Y15: =30 | Z15: {\"RAIL_ACCEL_REC_RANGE_G\":16} | AA15: 1 | AC15: ="{""" & $D$1 & """:""" & $D15 & "," & $E15 & "," & $F15 & """,""" & $G$1 & """:""" & $G15 & "," & $H15 & "," & $I15 & "," & $J15 & "," & $K15 & "," & $L15 & """,""" & $M$1 & """:""" & $M15 & "," & $N15 & "," & $O15 & """,""" & $P$1 & """:""" & $P15 & "," & $Q15 & "," & $R15 & """,""" & $S$1 & """:""" & $S15 & "," & $T15 & "," & $U15 & "," & $V15 & "," & $W15 & "," & $X15 & """,""" & $AB$1 & """:""" & $AB15 & """,""" & $Y$1 & """:""" & $Y15 & """,""" & $Z$1 & """:""" & $Z15 & """,""" & $AA$1 & """:""" & $AA15 & """}"
A16: =A15+1 | B16: Reserved-1 | C16: Normal operation mode | D16: =D15 | E16: =E15 | F16: =F15 | G16: =G15 | H16: 400 | I16: =3600*4 | J16: =3600*12 | K16: =K15 | L16: =200*L$1 | M16: =M15 | N16: =N15 | O16: =O15 | P16: =P15 | Q16: =Q15 | R16: =R15 | S16: =S15 | T16: =T15 | ... X16: =X15 | Y16: =30 | Z16: {\"RAIL_ACCEL_REC_RANGE_G\":16} | AA16: 0 | AC16: ="{""" & $D$1 & """:""" & $D16 & "," & $E16 & "," & $F16 & """,""" & $G$1 & """:""" & $G16 & "," & $H16 & "," & $I16 & "," & $J16 & "," & $K16 & "," & $L16 & """,""" & $M$1 & """:""" & $M16 & "," & $N16 & "," & $O16 & """,""" & $P$1 & """:""" & $P16 & "," & $Q16 & "," & $R16 & """,""" & $S$1 & """:""" & $S16 & "," & $T16 & "," & $U16 & "," & $V16 & "," & $W16 & "," & $X16 & """,""" & $AB$1 & """:""" & $AB16 & """,""" & $Y$1 & """:""" & $Y16 & """,""" & $Z$1 & """:""" & $Z16 & """,""" & $AA$1 & """:""" & $AA16 & """}"
A17: =A16+1 | B17: Reserved-2 | C17: Fast mode for faster data collection | D17: =D16 | E17: =E16 | F17: =F16 | G17: =G16 | H17: 300 | I17: =3600*1 | J17: =3*3600 | K17: =K16 | L17: =200*L$1 | M17: =M16 | N17: =N16 | O17: =O16 | P17: =P16 | Q17: =Q16 | R17: =R16 | S17: =S16 | T17: =T16 | ... X17: =X16 | Y17: =30 | Z17: {\"RAIL_ACCEL_REC_RANGE_G\":16} | AA17: 0 | AC17: ="{""" & $D$1 & """:""" & $D17 & "," & $E17 & "," & $F17 & """,""" & $G$1 & """:""" & $G17 & "," & $H17 & "," & $I17 & "," & $J17 & "," & $K17 & "," & $L17 & """,""" & $M$1 & """:""" & $M17 & "," & $N17 & "," & $O17 & """,""" & $P$1 & """:""" & $P17 & "," & $Q17 & "," & $R17 & """,""" & $S$1 & """:""" & $S17 & "," & $T17 & "," & $U17 & "," & $V17 & "," & $W17 & "," & $X17 & """,""" & $AB$1 & """:""" & $AB17 & """,""" & $Y$1 & """:""" & $Y17 & """,""" & $Z$1 & """:""" & $Z17 & """,""" & $AA$1 & """:""" & $AA17 & """}"
A18: =A17+1 | B18: TEST_F3-10min-10min | C18: Testing parameters 3 | D18: 0.000000 | E18: 0.000000 | F18: =F15 | G18: =G17 | H18: 120 | I18: 600 | J18: 600 | K18: 10 | L18: =120*L$1 | M18: =M16 | N18: =N16 | O18: =O16 | P18: =P16 | Q18: =Q16 | R18: =R16 | S18: =S16 | T18: =T16 | ... X18: =X16 | Y18: =30,sensors.process=1,sensors.comm=1 | Z18: {\"RAIL_ACCEL_REC_RANGE_G\":16} | AA18: 0 | AC18: ="{""" & $D$1 & """:""" & $D18 & "," & $E18 & "," & $F18 & """,""" & $G$1 & """:""" & $G18 & "," & $H18 & "," & $I18 & "," & $J18 & "," & $K18 & "," & $L18 & """,""" & $M$1 & """:""" & $M18 & "," & $N18 & "," & $O18 & """,""" & $P$1 & """:""" & $P18 & "," & $Q18 & "," & $R18 & """,""" & $S$1 & """:""" & $S18 & "," & $T18 & "," & $U18 & "," & $V18 & "," & $W18 & "," & $X18 & """,""" & $AB$1 & """:""" & $AB18 & """,""" & $Y$1 & """:""" & $Y18 & """,""" & $Z$1 & """:""" & $Z18 & """,""" & $AA$1 & """:""" & $AA18 & """}"
A19: =A18+1 | B19: TEST_F4-1h-1h | C19: Testing parameters 4 | D19: 0.000000 | E19: 0.000000 | F19: =F16 | G19: =G18 | H19: 600 | I19: 3600 | J19: 3600 | K19: 10 | L19: =200*L$1 | M19: =M17 | N19: =N17 | O19: =O17 | P19: =P17 | Q19: =Q17 | R19: =R17 | S19: =S17 | T19: =T17 | ... X19: =X17 | Y19: =30,sensors.process=1,sensors.comm=1 | Z19: {\"RAIL_ACCEL_REC_RANGE_G\":16} | AA19: 0 | AB19: http://ec2-35-157-185-34.eu-central-1.compute.amazonaws.com:8090/sensor?2.1/0.26/ | AC19: ="{""" & $D$1 & """:""" & $D19 & "," & $E19 & "," & $F19 & """,""" & $G$1 & """:""" & $G19 & "," & $H19 & "," & $I19 & "," & $J19 & "," & $K19 & "," & $L19 & """,""" & $M$1 & """:""" & $M19 & "," & $N19 & "," & $O19 & """,""" & $P$1 & """:""" & $P19 & "," & $Q19 & "," & $R19 & """,""" & $S$1 & """:""" & $S19 & "," & $T19 & "," & $U19 & "," & $V19 & "," & $W19 & "," & $X19 & """,""" & $AB$1 & """:""" & $AB19 & """,""" & $Y$1 & """:""" & $Y19 & """,""" & $Z$1 & """:""" & $Z19 & """,""" & $AA$1 & """:""" & $AA19 & """}"
A20: =A19+1 | B20: NO_SPEED_2h | C20: Speed filter off | D20: 0.000000 | E20: 0.000000 | F20: 10.000000 | G20: =G19 | H20: 150 | I20: =3600*2 | J20: =3600*2 | K20: =K19 | L20: =120*L$1 | M20: =M19 | N20: =N19 | O20: =O19 | P20: =P19 | Q20: =Q19 | R20: =R19 | S20: =S19 | T20: =T19 | ... X20: =X19 | Y20: =30 | Z20: {\"RAIL_ACCEL_REC_RANGE_G\":16} | AA20: 0 | AC20: ="{""" & $D$1 & """:""" & $D20 & "," & $E20 & "," & $F20 & """,""" & $G$1 & """:""" & $G20 & "," & $H20 & "," & $I20 & "," & $J20 & "," & $K20 & "," & $L20 & """,""" & $M$1 & """:""" & $M20 & "," & $N20 & "," & $O20 & """,""" & $P$1 & """:""" & $P20 & "," & $Q20 & "," & $R20 & """,""" & $S$1 & """:""" & $S20 & "," & $T20 & "," & $U20 & "," & $V20 & "," & $W20 & "," & $X20 & """,""" & $AB$1 & """:""" & $AB20 & """,""" & $Y$1 & """:""" & $Y20 & """,""" & $Z$1 & """:""" & $Z20 & """,""" & $AA$1 & """:""" & $AA20 & """}"
A21: 19 | B21: One-sensor-fast-test | C21: Fast mode for one sensor | D21: =D20 | E21: =E20 | F21: =F20 | G21: 40 | H21: 60 | I21: 300 | J21: 300 | K21: 4 | L21: =60*L$1 | M21: 1 | N21: 60 | O21: 300 | P21: 2.500000 | Q21: 3.000000 | R21: 3600 | S21: =S20 | T21: =T20 | U21: =U20 | V21: =V20 | W21: =W20 | X21: =X20 | Y21: =30,sensors.process=1,sensors.comm=1 | Z21: {\"RAIL_ACCEL_REC_RANGE_G\":16} | AA21: 0 | AC21: ="{""" & $D$1 & """:""" & $D21 & "," & $E21 & "," & $F21 & """,""" & $G$1 & """:""" & $G21 & "," & $H21 & "," & $I21 & "," & $J21 & "," & $K21 & "," & $L21 & """,""" & $M$1 & """:""" & $M21 & "," & $N21 & "," & $O21 & """,""" & $P$1 & """:""" & $P21 & "," & $Q21 & "," & $R21 & """,""" & $S$1 & """:""" & $S21 & "," & $T21 & "," & $U21 & "," & $V21 & "," & $W21 & "," & $X21 & """,""" & $AB$1 & """:""" & $AB21 & """,""" & $Y$1 & """:""" & $Y21 & """,""" & $Z$1 & """:""" & $Z21 & """,""" & $AA$1 & """:""" & $AA21 & """}"
A22: =A21+1 | B22: Shipping-no-GW | C22: Mode for shipping sensors only | D22: 15.000000 | E22: 25.000000 | F22: 10.000000 | G22: 40 | H22: 600 | I22: 3600 | J22: 3600 | K22: 10 | L22: =3600*4*L$1 | M22: 1 | N22: 60 | O22: 300 | P22: 2.500000 | Q22: 3.000000 | R22: 3600 | S22: 0.000000 | T22: 1.500000 | U22: 0.200000 | V22: 2.000000 | W22: 0.200000 | X22: active | Y22: =30 | Z22: {\"RAIL_ACCEL_REC_RANGE_G\":16} | AA22: 0 | AC22: ="{""" & $D$1 & """:""" & $D22 & "," & $E22 & "," & $F22 & """,""" & $G$1 & """:""" & $G22 & "," & $H22 & "," & $I22 & "," & $J22 & "," & $K22 & "," & $L22 & """,""" & $M$1 & """:""" & $M22 & "," & $N22 & "," & $O22 & """,""" & $P$1 & """:""" & $P22 & "," & $Q22 & "," & $R22 & """,""" & $S$1 & """:""" & $S22 & "," & $T22 & "," & $U22 & "," & $V22 & "," & $W22 & "," & $X22 & """,""" & $AB$1 & """:""" & $AB22 & """,""" & $Y$1 & """:""" & $Y22 & """,""" & $Z$1 & """:""" & $Z22 & """,""" & $AA$1 & """:""" & $AA22 & """}"
A23: =A22+1 | B23: DD_ONLY_discovery | C23: Discovery mode for sensors in office | D23: 15.000000 | E23: 25.000000 | F23: 10.000000 | G23: 40 | H23: 3700 | I23: =H23*1.2 | J23: 1800 | K23: 10 | L23: =1800*L$1 | M23: 1 | N23: 60 | O23: 300 | P23: 2.500000 | Q23: 3.000000 | R23: 3600 | S23: 0.000000 | T23: 1.500000 | U23: 0.200000 | V23: 2.000000 | W23: 0.200000 | X23: active | Y23: =30,sensors.process=1,sensors.comm=1 | Z23: {\"RAIL_ACCEL_REC_RANGE_G\":16} | AA23: 0 | AB23: http://ec2-35-157-185-34.eu-central-1.compute.amazonaws.com:8090/sensor?2.2/0.30/ | AC23: ="{""" & $D$1 & """:""" & $D23 & "," & $E23 & "," & $F23 & """,""" & $G$1 & """:""" & $G23 & "," & $H23 & "," & $I23 & "," & $J23 & "," & $K23 & "," & $L23 & """,""" & $M$1 & """:""" & $M23 & "," & $N23 & "," & $O23 & """,""" & $P$1 & """:""" & $P23 & "," & $Q23 & "," & $R23 & """,""" & $S$1 & """:""" & $S23 & "," & $T23 & "," & $U23 & "," & $V23 & "," & $W23 & "," & $X23 & """,""" & $AB$1 & """:""" & $AB23 & """,""" & $Y$1 & """:""" & $Y23 & """,""" & $Z$1 & """:""" & $Z23 & """,""" & $AA$1 & """:""" & $AA23 & """}"

Sheet Wagons
A1: Wagon Nr. | B1: Wagon type | C1: Description
A2: 1 | B2: Shipping | C2: Mode for shipping devices
A3: =A2+1 | B3: Slow | C3: Slow mode for low power operation
A4: =A3+1 | B4: Normal | C4: Normal operation mode
A5: =A4+1 | B5: Fast | C5: Fast mode for faster data collection
A6: =A5+1 | B6: Super Fast | C6: High energy consumption mode
A7: 6 | B7: Assembly | C7: For assembling sensors
A8: 7 | B8: New FW Test | C8: For LTG tests

Sheet Wagon_types
